{
 "cells": [
  {
   "cell_type": "markdown",
   "metadata": {
    "id": "jXEQk9Q5o9bv"
   },
   "source": [
    "## Import necessary libraries"
   ]
  },
  {
   "cell_type": "code",
   "execution_count": 9,
   "metadata": {
    "id": "8CAlAAkqoSwG"
   },
   "outputs": [],
   "source": [
    "import os\n",
    "\n",
    "import numpy as np\n",
    "from keras.preprocessing.image import ImageDataGenerator\n",
    "from keras.layers import Dense, Conv2D, MaxPooling2D, GlobalAveragePooling2D, \\\n",
    "                          Flatten, Activation, Dropout\n",
    "from keras.layers.normalization import BatchNormalization\n",
    "from keras.models import Model, Sequential\n",
    "from keras.applications.resnet50 import ResNet50\n",
    "from keras import regularizers\n",
    "from keras.optimizers import Adam\n",
    "from keras.callbacks import ModelCheckpoint\n",
    "import matplotlib.pyplot as plt"
   ]
  },
  {
   "cell_type": "markdown",
   "metadata": {
    "id": "lTDtxc6ZjbQ7"
   },
   "source": [
    "## Define hyperparameters"
   ]
  },
  {
   "cell_type": "code",
   "execution_count": 16,
   "metadata": {
    "id": "ChAyqhKfBhbt"
   },
   "outputs": [
    {
     "name": "stdout",
     "output_type": "stream",
     "text": [
      "ERROR! Session/line number was not unique in database. History logging moved to new session 34\n",
      "sh: 0: getcwd() failed: No such file or directory\r\n"
     ]
    }
   ],
   "source": [
    "BATCH_SIZE = 32\n",
    "EPOCHS = 100\n",
    "IMG_HEIGHT = 48\n",
    "IMG_WIDTH = 48\n",
    "NUM_OUTPUTS = 5\n",
    "LEARNING_RATE = 1e-4\n",
    "DROPOUT_RATE = 0.3\n",
    "L2_WEIGHT_DECAY = 1e-6\n",
    "\n",
    "!ls"
   ]
  },
  {
   "cell_type": "markdown",
   "metadata": {
    "id": "UQDpg4DGpeL5"
   },
   "source": [
    "The dataset has the following directory structure:\n",
    "\n",
    "<pre>\n",
    "<b>dataset</b>\n",
    "|__ <b>train</b>\n",
    "    |______ <b>angry</b>: [0.jpg, 1.jpg, 10.jpg, ...]\n",
    "    |______ <b>happy</b>: [100.jpg, 10000.jpg, 10001.jpg, ...]\n",
    "    |______ <b>neutral</b>: [1000.jpg, 10003.jpg, 10014.jpg, ...]\n",
    "    |______ <b>sad</b>: [10006.jpg, 10008.jpg, 1001.jpg, ...]\n",
    "    |______ <b>surprise</b>: [10007.jpg, 10009.jpg, 10011.jpg, ...]\n",
    "|__ <b>validation</b>\n",
    "    |______ <b>angry</b>: [10052.jpg, 10065.jpg, 10079.jpg, ....]\n",
    "    |______ <b>happy</b>: [10019.jpg, 10023.jpg, 10074.jpg, ...]\n",
    "    |______ <b>neutral</b>: [10033.jpg, 10048.jpg, 10068.jpg, ...]\n",
    "    |______ <b>sad</b>: [10004.jpg, 1003.jpg, 10031.jpg, ...]\n",
    "    |______ <b>surprise</b>: [10056.jpg, 10097.jpg, 10162.jpg, ...]\n",
    "</pre>"
   ]
  },
  {
   "cell_type": "code",
   "execution_count": null,
   "metadata": {
    "id": "CsFaiWO8q0Fa"
   },
   "outputs": [
    {
     "name": "stderr",
     "output_type": "stream",
     "text": [
      "ERROR:root:Internal Python error in the inspect module.\n",
      "Below is the traceback from this internal error.\n",
      "\n",
      "ERROR:root:Internal Python error in the inspect module.\n",
      "Below is the traceback from this internal error.\n",
      "\n",
      "ERROR:root:Internal Python error in the inspect module.\n",
      "Below is the traceback from this internal error.\n",
      "\n"
     ]
    },
    {
     "name": "stdout",
     "output_type": "stream",
     "text": [
      "Traceback (most recent call last):\n",
      "  File \"/home/ubuntu/.local/lib/python3.8/site-packages/IPython/core/interactiveshell.py\", line 3418, in run_code\n",
      "    exec(code_obj, self.user_global_ns, self.user_ns)\n",
      "  File \"<ipython-input-16-bab4c34159e1>\", line 16, in <module>\n",
      "    num_angry_tr = len(os.listdir(train_angry_dir))\n",
      "FileNotFoundError: [Errno 2] No such file or directory: './dataset/train/angry'\n",
      "\n",
      "During handling of the above exception, another exception occurred:\n",
      "\n",
      "Traceback (most recent call last):\n",
      "  File \"/home/ubuntu/.local/lib/python3.8/site-packages/IPython/core/interactiveshell.py\", line 2045, in showtraceback\n",
      "    stb = value._render_traceback_()\n",
      "AttributeError: 'FileNotFoundError' object has no attribute '_render_traceback_'\n",
      "\n",
      "During handling of the above exception, another exception occurred:\n",
      "\n",
      "Traceback (most recent call last):\n",
      "  File \"/home/ubuntu/.local/lib/python3.8/site-packages/IPython/core/ultratb.py\", line 1170, in get_records\n",
      "    return _fixed_getinnerframes(etb, number_of_lines_of_context, tb_offset)\n",
      "  File \"/home/ubuntu/.local/lib/python3.8/site-packages/IPython/core/ultratb.py\", line 316, in wrapped\n",
      "    return f(*args, **kwargs)\n",
      "  File \"/home/ubuntu/.local/lib/python3.8/site-packages/IPython/core/ultratb.py\", line 350, in _fixed_getinnerframes\n",
      "    records = fix_frame_records_filenames(inspect.getinnerframes(etb, context))\n",
      "  File \"/usr/lib/python3.8/inspect.py\", line 1503, in getinnerframes\n",
      "    frameinfo = (tb.tb_frame,) + getframeinfo(tb, context)\n",
      "  File \"/usr/lib/python3.8/inspect.py\", line 1461, in getframeinfo\n",
      "    filename = getsourcefile(frame) or getfile(frame)\n",
      "  File \"/usr/lib/python3.8/inspect.py\", line 708, in getsourcefile\n",
      "    if getattr(getmodule(object, filename), '__loader__', None) is not None:\n",
      "  File \"/usr/lib/python3.8/inspect.py\", line 737, in getmodule\n",
      "    file = getabsfile(object, _filename)\n",
      "  File \"/usr/lib/python3.8/inspect.py\", line 721, in getabsfile\n",
      "    return os.path.normcase(os.path.abspath(_filename))\n",
      "  File \"/usr/lib/python3.8/posixpath.py\", line 379, in abspath\n",
      "    cwd = os.getcwd()\n",
      "FileNotFoundError: [Errno 2] No such file or directory\n",
      "ERROR! Session/line number was not unique in database. History logging moved to new session 33\n",
      "Traceback (most recent call last):\n",
      "  File \"/home/ubuntu/.local/lib/python3.8/site-packages/IPython/core/interactiveshell.py\", line 3418, in run_code\n",
      "    exec(code_obj, self.user_global_ns, self.user_ns)\n",
      "  File \"<ipython-input-16-bab4c34159e1>\", line 16, in <module>\n",
      "    num_angry_tr = len(os.listdir(train_angry_dir))\n",
      "FileNotFoundError: [Errno 2] No such file or directory: './dataset/train/angry'\n",
      "\n",
      "During handling of the above exception, another exception occurred:\n",
      "\n",
      "Traceback (most recent call last):\n",
      "  File \"/home/ubuntu/.local/lib/python3.8/site-packages/IPython/core/interactiveshell.py\", line 2045, in showtraceback\n",
      "    stb = value._render_traceback_()\n",
      "AttributeError: 'FileNotFoundError' object has no attribute '_render_traceback_'\n",
      "\n",
      "During handling of the above exception, another exception occurred:\n",
      "\n",
      "Traceback (most recent call last):\n",
      "  File \"/home/ubuntu/.local/lib/python3.8/site-packages/IPython/core/interactiveshell.py\", line 3338, in run_ast_nodes\n",
      "    if (await self.run_code(code, result,  async_=asy)):\n",
      "  File \"/home/ubuntu/.local/lib/python3.8/site-packages/IPython/core/interactiveshell.py\", line 3435, in run_code\n",
      "    self.showtraceback(running_compiled_code=True)\n",
      "  File \"/home/ubuntu/.local/lib/python3.8/site-packages/IPython/core/interactiveshell.py\", line 2047, in showtraceback\n",
      "    stb = self.InteractiveTB.structured_traceback(etype,\n",
      "  File \"/home/ubuntu/.local/lib/python3.8/site-packages/IPython/core/ultratb.py\", line 1436, in structured_traceback\n",
      "    return FormattedTB.structured_traceback(\n",
      "  File \"/home/ubuntu/.local/lib/python3.8/site-packages/IPython/core/ultratb.py\", line 1336, in structured_traceback\n",
      "    return VerboseTB.structured_traceback(\n",
      "  File \"/home/ubuntu/.local/lib/python3.8/site-packages/IPython/core/ultratb.py\", line 1193, in structured_traceback\n",
      "    formatted_exception = self.format_exception_as_a_whole(etype, evalue, etb, number_of_lines_of_context,\n",
      "  File \"/home/ubuntu/.local/lib/python3.8/site-packages/IPython/core/ultratb.py\", line 1151, in format_exception_as_a_whole\n",
      "    last_unique, recursion_repeat = find_recursion(orig_etype, evalue, records)\n",
      "  File \"/home/ubuntu/.local/lib/python3.8/site-packages/IPython/core/ultratb.py\", line 451, in find_recursion\n",
      "    return len(records), 0\n",
      "TypeError: object of type 'NoneType' has no len()\n",
      "\n",
      "During handling of the above exception, another exception occurred:\n",
      "\n",
      "Traceback (most recent call last):\n",
      "  File \"/home/ubuntu/.local/lib/python3.8/site-packages/IPython/core/interactiveshell.py\", line 2045, in showtraceback\n",
      "    stb = value._render_traceback_()\n",
      "AttributeError: 'TypeError' object has no attribute '_render_traceback_'\n",
      "\n",
      "During handling of the above exception, another exception occurred:\n",
      "\n",
      "Traceback (most recent call last):\n",
      "  File \"/home/ubuntu/.local/lib/python3.8/site-packages/IPython/core/ultratb.py\", line 1170, in get_records\n",
      "    return _fixed_getinnerframes(etb, number_of_lines_of_context, tb_offset)\n",
      "  File \"/home/ubuntu/.local/lib/python3.8/site-packages/IPython/core/ultratb.py\", line 316, in wrapped\n",
      "    return f(*args, **kwargs)\n",
      "  File \"/home/ubuntu/.local/lib/python3.8/site-packages/IPython/core/ultratb.py\", line 350, in _fixed_getinnerframes\n",
      "    records = fix_frame_records_filenames(inspect.getinnerframes(etb, context))\n",
      "  File \"/usr/lib/python3.8/inspect.py\", line 1503, in getinnerframes\n",
      "    frameinfo = (tb.tb_frame,) + getframeinfo(tb, context)\n",
      "  File \"/usr/lib/python3.8/inspect.py\", line 1461, in getframeinfo\n",
      "    filename = getsourcefile(frame) or getfile(frame)\n",
      "  File \"/usr/lib/python3.8/inspect.py\", line 708, in getsourcefile\n",
      "    if getattr(getmodule(object, filename), '__loader__', None) is not None:\n",
      "  File \"/usr/lib/python3.8/inspect.py\", line 737, in getmodule\n",
      "    file = getabsfile(object, _filename)\n",
      "  File \"/usr/lib/python3.8/inspect.py\", line 721, in getabsfile\n",
      "    return os.path.normcase(os.path.abspath(_filename))\n",
      "  File \"/usr/lib/python3.8/posixpath.py\", line 379, in abspath\n",
      "    cwd = os.getcwd()\n",
      "FileNotFoundError: [Errno 2] No such file or directory\n",
      "Traceback (most recent call last):\n",
      "  File \"/home/ubuntu/.local/lib/python3.8/site-packages/IPython/core/interactiveshell.py\", line 3418, in run_code\n",
      "    exec(code_obj, self.user_global_ns, self.user_ns)\n",
      "  File \"<ipython-input-16-bab4c34159e1>\", line 16, in <module>\n",
      "    num_angry_tr = len(os.listdir(train_angry_dir))\n",
      "FileNotFoundError: [Errno 2] No such file or directory: './dataset/train/angry'\n",
      "\n",
      "During handling of the above exception, another exception occurred:\n",
      "\n",
      "Traceback (most recent call last):\n",
      "  File \"/home/ubuntu/.local/lib/python3.8/site-packages/IPython/core/interactiveshell.py\", line 2045, in showtraceback\n",
      "    stb = value._render_traceback_()\n",
      "AttributeError: 'FileNotFoundError' object has no attribute '_render_traceback_'\n",
      "\n",
      "During handling of the above exception, another exception occurred:\n",
      "\n",
      "Traceback (most recent call last):\n",
      "  File \"/home/ubuntu/.local/lib/python3.8/site-packages/IPython/core/interactiveshell.py\", line 3338, in run_ast_nodes\n",
      "    if (await self.run_code(code, result,  async_=asy)):\n",
      "  File \"/home/ubuntu/.local/lib/python3.8/site-packages/IPython/core/interactiveshell.py\", line 3435, in run_code\n",
      "    self.showtraceback(running_compiled_code=True)\n",
      "  File \"/home/ubuntu/.local/lib/python3.8/site-packages/IPython/core/interactiveshell.py\", line 2047, in showtraceback\n",
      "    stb = self.InteractiveTB.structured_traceback(etype,\n",
      "  File \"/home/ubuntu/.local/lib/python3.8/site-packages/IPython/core/ultratb.py\", line 1436, in structured_traceback\n",
      "    return FormattedTB.structured_traceback(\n",
      "  File \"/home/ubuntu/.local/lib/python3.8/site-packages/IPython/core/ultratb.py\", line 1336, in structured_traceback\n",
      "    return VerboseTB.structured_traceback(\n",
      "  File \"/home/ubuntu/.local/lib/python3.8/site-packages/IPython/core/ultratb.py\", line 1193, in structured_traceback\n",
      "    formatted_exception = self.format_exception_as_a_whole(etype, evalue, etb, number_of_lines_of_context,\n",
      "  File \"/home/ubuntu/.local/lib/python3.8/site-packages/IPython/core/ultratb.py\", line 1151, in format_exception_as_a_whole\n",
      "    last_unique, recursion_repeat = find_recursion(orig_etype, evalue, records)\n",
      "  File \"/home/ubuntu/.local/lib/python3.8/site-packages/IPython/core/ultratb.py\", line 451, in find_recursion\n",
      "    return len(records), 0\n",
      "TypeError: object of type 'NoneType' has no len()\n",
      "\n",
      "During handling of the above exception, another exception occurred:\n",
      "\n",
      "Traceback (most recent call last):\n",
      "  File \"/home/ubuntu/.local/lib/python3.8/site-packages/IPython/core/interactiveshell.py\", line 2045, in showtraceback\n",
      "    stb = value._render_traceback_()\n",
      "AttributeError: 'TypeError' object has no attribute '_render_traceback_'\n",
      "\n",
      "During handling of the above exception, another exception occurred:\n",
      "\n",
      "Traceback (most recent call last):\n",
      "  File \"/home/ubuntu/.local/lib/python3.8/site-packages/IPython/core/interactiveshell.py\", line 2923, in _run_cell\n",
      "    return runner(coro)\n",
      "  File \"/home/ubuntu/.local/lib/python3.8/site-packages/IPython/core/async_helpers.py\", line 68, in _pseudo_sync_runner\n",
      "    coro.send(None)\n",
      "  File \"/home/ubuntu/.local/lib/python3.8/site-packages/IPython/core/interactiveshell.py\", line 3146, in run_cell_async\n",
      "    has_raised = await self.run_ast_nodes(code_ast.body, cell_name,\n",
      "  File \"/home/ubuntu/.local/lib/python3.8/site-packages/IPython/core/interactiveshell.py\", line 3357, in run_ast_nodes\n",
      "    self.showtraceback()\n",
      "  File \"/home/ubuntu/.local/lib/python3.8/site-packages/IPython/core/interactiveshell.py\", line 2047, in showtraceback\n",
      "    stb = self.InteractiveTB.structured_traceback(etype,\n",
      "  File \"/home/ubuntu/.local/lib/python3.8/site-packages/IPython/core/ultratb.py\", line 1436, in structured_traceback\n",
      "    return FormattedTB.structured_traceback(\n",
      "  File \"/home/ubuntu/.local/lib/python3.8/site-packages/IPython/core/ultratb.py\", line 1336, in structured_traceback\n",
      "    return VerboseTB.structured_traceback(\n",
      "  File \"/home/ubuntu/.local/lib/python3.8/site-packages/IPython/core/ultratb.py\", line 1211, in structured_traceback\n",
      "    formatted_exceptions += self.format_exception_as_a_whole(etype, evalue, etb, lines_of_context,\n",
      "  File \"/home/ubuntu/.local/lib/python3.8/site-packages/IPython/core/ultratb.py\", line 1151, in format_exception_as_a_whole\n",
      "    last_unique, recursion_repeat = find_recursion(orig_etype, evalue, records)\n",
      "  File \"/home/ubuntu/.local/lib/python3.8/site-packages/IPython/core/ultratb.py\", line 451, in find_recursion\n",
      "    return len(records), 0\n",
      "TypeError: object of type 'NoneType' has no len()\n",
      "\n",
      "During handling of the above exception, another exception occurred:\n",
      "\n",
      "Traceback (most recent call last):\n",
      "  File \"/home/ubuntu/.local/lib/python3.8/site-packages/IPython/core/interactiveshell.py\", line 2045, in showtraceback\n",
      "    stb = value._render_traceback_()\n",
      "AttributeError: 'TypeError' object has no attribute '_render_traceback_'\n",
      "\n",
      "During handling of the above exception, another exception occurred:\n",
      "\n",
      "Traceback (most recent call last):\n",
      "  File \"/home/ubuntu/.local/lib/python3.8/site-packages/IPython/core/ultratb.py\", line 1170, in get_records\n",
      "    return _fixed_getinnerframes(etb, number_of_lines_of_context, tb_offset)\n",
      "  File \"/home/ubuntu/.local/lib/python3.8/site-packages/IPython/core/ultratb.py\", line 316, in wrapped\n",
      "    return f(*args, **kwargs)\n",
      "  File \"/home/ubuntu/.local/lib/python3.8/site-packages/IPython/core/ultratb.py\", line 350, in _fixed_getinnerframes\n",
      "    records = fix_frame_records_filenames(inspect.getinnerframes(etb, context))\n",
      "  File \"/usr/lib/python3.8/inspect.py\", line 1503, in getinnerframes\n",
      "    frameinfo = (tb.tb_frame,) + getframeinfo(tb, context)\n",
      "  File \"/usr/lib/python3.8/inspect.py\", line 1461, in getframeinfo\n",
      "    filename = getsourcefile(frame) or getfile(frame)\n",
      "  File \"/usr/lib/python3.8/inspect.py\", line 708, in getsourcefile\n",
      "    if getattr(getmodule(object, filename), '__loader__', None) is not None:\n",
      "  File \"/usr/lib/python3.8/inspect.py\", line 737, in getmodule\n",
      "    file = getabsfile(object, _filename)\n",
      "  File \"/usr/lib/python3.8/inspect.py\", line 721, in getabsfile\n",
      "    return os.path.normcase(os.path.abspath(_filename))\n",
      "  File \"/usr/lib/python3.8/posixpath.py\", line 379, in abspath\n",
      "    cwd = os.getcwd()\n",
      "FileNotFoundError: [Errno 2] No such file or directory\n"
     ]
    }
   ],
   "source": [
    "train_dir = os.path.join(\"./dataset\", \"train\")\n",
    "validation_dir = os.path.join(\"./dataset\", \"validation\")\n",
    "\n",
    "train_angry_dir = os.path.join(train_dir, \"angry\")\n",
    "train_happy_dir = os.path.join(train_dir, \"happy\")\n",
    "train_neutral_dir = os.path.join(train_dir, \"neutral\")\n",
    "train_sad_dir = os.path.join(train_dir, \"sad\")\n",
    "train_surprise_dir = os.path.join(train_dir, \"surprise\")\n",
    "\n",
    "validation_angry_dir = os.path.join(validation_dir, \"angry\")\n",
    "validation_happy_dir = os.path.join(validation_dir, \"happy\")\n",
    "validation_neutral_dir = os.path.join(validation_dir, \"neutral\")\n",
    "validation_sad_dir = os.path.join(validation_dir, \"sad\")\n",
    "validation_surprise_dir = os.path.join(validation_dir, \"surprise\")\n",
    "\n",
    "num_angry_tr = len(os.listdir(train_angry_dir))\n",
    "num_happy_tr = len(os.listdir(train_happy_dir))\n",
    "num_neutral_tr = len(os.listdir(train_neutral_dir))\n",
    "num_sad_tr = len(os.listdir(train_sad_dir))\n",
    "num_surprise_tr = len(os.listdir(train_surprise_dir))\n",
    "\n",
    "num_angry_val = len(os.listdir(validation_angry_dir))\n",
    "num_happy_val = len(os.listdir(validation_happy_dir))\n",
    "num_neutral_val = len(os.listdir(validation_neutral_dir))\n",
    "num_sad_val = len(os.listdir(validation_sad_dir))\n",
    "num_surprise_val = len(os.listdir(validation_surprise_dir))\n",
    "\n",
    "total_train = num_angry_tr + num_happy_tr + num_neutral_tr + num_sad_tr + num_surprise_tr\n",
    "total_val = num_angry_val + num_happy_val + num_neutral_val + num_sad_val + num_surprise_val\n",
    "\n",
    "# debug\n",
    "print('total # of training set :', total_train)\n",
    "print('total # of train_angry :', num_angry_tr)\n",
    "print('total # of train_happy :', num_happy_tr)\n",
    "print('total # of train_neutral :', num_neutral_tr)\n",
    "print('total # of train_sad :', num_sad_tr)\n",
    "print('total # of train_surprise :', num_surprise_tr, \"\\n\")\n",
    "\n",
    "print('total # of validation set :', total_val)\n",
    "print('total # of validation_angry :', num_angry_val)\n",
    "print('total # of validation_happy :', num_happy_val)\n",
    "print('total # of validation_neutral :', num_neutral_val)\n",
    "print('total # of validation_sad :', num_sad_val)\n",
    "print('total # of validation_surprise :', num_surprise_val)"
   ]
  },
  {
   "cell_type": "markdown",
   "metadata": {
    "id": "9QEoWgeMEI2B"
   },
   "source": [
    "## Preprocess the dataset"
   ]
  },
  {
   "cell_type": "code",
   "execution_count": 11,
   "metadata": {
    "id": "Egovd3zgCkTo"
   },
   "outputs": [],
   "source": [
    "train_image_generator = ImageDataGenerator(rescale=1./255) # Generator for our training data\n",
    "validation_image_generator = ImageDataGenerator(rescale=1./255) # Generator for our validation data"
   ]
  },
  {
   "cell_type": "code",
   "execution_count": null,
   "metadata": {
    "colab": {
     "base_uri": "https://localhost:8080/"
    },
    "id": "R-WBha-HCzJj",
    "outputId": "8a912b10-e1d9-4f60-d27e-ea8a48fff494"
   },
   "outputs": [
    {
     "name": "stderr",
     "output_type": "stream",
     "text": [
      "ERROR:root:Internal Python error in the inspect module.\n",
      "Below is the traceback from this internal error.\n",
      "\n",
      "ERROR:root:Internal Python error in the inspect module.\n",
      "Below is the traceback from this internal error.\n",
      "\n",
      "ERROR:root:Internal Python error in the inspect module.\n",
      "Below is the traceback from this internal error.\n",
      "\n"
     ]
    },
    {
     "name": "stdout",
     "output_type": "stream",
     "text": [
      "ERROR! Session/line number was not unique in database. History logging moved to new session 26\n",
      "Traceback (most recent call last):\n",
      "  File \"/home/ubuntu/.local/lib/python3.8/site-packages/IPython/core/interactiveshell.py\", line 3418, in run_code\n",
      "    exec(code_obj, self.user_global_ns, self.user_ns)\n",
      "  File \"<ipython-input-12-80eb5ce7ce9f>\", line 1, in <module>\n",
      "    train_data_gen = train_image_generator.flow_from_directory(\n",
      "  File \"/home/ubuntu/.local/lib/python3.8/site-packages/tensorflow/python/keras/preprocessing/image.py\", line 943, in flow_from_directory\n",
      "    return DirectoryIterator(\n",
      "  File \"/home/ubuntu/.local/lib/python3.8/site-packages/tensorflow/python/keras/preprocessing/image.py\", line 381, in __init__\n",
      "    super(DirectoryIterator, self).__init__(\n",
      "  File \"/home/ubuntu/.local/lib/python3.8/site-packages/keras_preprocessing/image/directory_iterator.py\", line 115, in __init__\n",
      "    for subdir in sorted(os.listdir(directory)):\n",
      "FileNotFoundError: [Errno 2] No such file or directory: './dataset/train'\n",
      "\n",
      "During handling of the above exception, another exception occurred:\n",
      "\n",
      "Traceback (most recent call last):\n",
      "  File \"/home/ubuntu/.local/lib/python3.8/site-packages/IPython/core/interactiveshell.py\", line 2045, in showtraceback\n",
      "    stb = value._render_traceback_()\n",
      "AttributeError: 'FileNotFoundError' object has no attribute '_render_traceback_'\n",
      "\n",
      "During handling of the above exception, another exception occurred:\n",
      "\n",
      "Traceback (most recent call last):\n",
      "  File \"/home/ubuntu/.local/lib/python3.8/site-packages/IPython/core/ultratb.py\", line 1170, in get_records\n",
      "    return _fixed_getinnerframes(etb, number_of_lines_of_context, tb_offset)\n",
      "  File \"/home/ubuntu/.local/lib/python3.8/site-packages/IPython/core/ultratb.py\", line 316, in wrapped\n",
      "    return f(*args, **kwargs)\n",
      "  File \"/home/ubuntu/.local/lib/python3.8/site-packages/IPython/core/ultratb.py\", line 350, in _fixed_getinnerframes\n",
      "    records = fix_frame_records_filenames(inspect.getinnerframes(etb, context))\n",
      "  File \"/usr/lib/python3.8/inspect.py\", line 1503, in getinnerframes\n",
      "    frameinfo = (tb.tb_frame,) + getframeinfo(tb, context)\n",
      "  File \"/usr/lib/python3.8/inspect.py\", line 1461, in getframeinfo\n",
      "    filename = getsourcefile(frame) or getfile(frame)\n",
      "  File \"/usr/lib/python3.8/inspect.py\", line 708, in getsourcefile\n",
      "    if getattr(getmodule(object, filename), '__loader__', None) is not None:\n",
      "  File \"/usr/lib/python3.8/inspect.py\", line 737, in getmodule\n",
      "    file = getabsfile(object, _filename)\n",
      "  File \"/usr/lib/python3.8/inspect.py\", line 721, in getabsfile\n",
      "    return os.path.normcase(os.path.abspath(_filename))\n",
      "  File \"/usr/lib/python3.8/posixpath.py\", line 379, in abspath\n",
      "    cwd = os.getcwd()\n",
      "FileNotFoundError: [Errno 2] No such file or directory\n",
      "Traceback (most recent call last):\n",
      "  File \"/home/ubuntu/.local/lib/python3.8/site-packages/IPython/core/interactiveshell.py\", line 3418, in run_code\n",
      "    exec(code_obj, self.user_global_ns, self.user_ns)\n",
      "  File \"<ipython-input-12-80eb5ce7ce9f>\", line 1, in <module>\n",
      "    train_data_gen = train_image_generator.flow_from_directory(\n",
      "  File \"/home/ubuntu/.local/lib/python3.8/site-packages/tensorflow/python/keras/preprocessing/image.py\", line 943, in flow_from_directory\n",
      "    return DirectoryIterator(\n",
      "  File \"/home/ubuntu/.local/lib/python3.8/site-packages/tensorflow/python/keras/preprocessing/image.py\", line 381, in __init__\n",
      "    super(DirectoryIterator, self).__init__(\n",
      "  File \"/home/ubuntu/.local/lib/python3.8/site-packages/keras_preprocessing/image/directory_iterator.py\", line 115, in __init__\n",
      "    for subdir in sorted(os.listdir(directory)):\n",
      "FileNotFoundError: [Errno 2] No such file or directory: './dataset/train'\n",
      "\n",
      "During handling of the above exception, another exception occurred:\n",
      "\n",
      "Traceback (most recent call last):\n",
      "  File \"/home/ubuntu/.local/lib/python3.8/site-packages/IPython/core/interactiveshell.py\", line 2045, in showtraceback\n",
      "    stb = value._render_traceback_()\n",
      "AttributeError: 'FileNotFoundError' object has no attribute '_render_traceback_'\n",
      "\n",
      "During handling of the above exception, another exception occurred:\n",
      "\n",
      "Traceback (most recent call last):\n",
      "  File \"/home/ubuntu/.local/lib/python3.8/site-packages/IPython/core/interactiveshell.py\", line 3338, in run_ast_nodes\n",
      "    if (await self.run_code(code, result,  async_=asy)):\n",
      "  File \"/home/ubuntu/.local/lib/python3.8/site-packages/IPython/core/interactiveshell.py\", line 3435, in run_code\n",
      "    self.showtraceback(running_compiled_code=True)\n",
      "  File \"/home/ubuntu/.local/lib/python3.8/site-packages/IPython/core/interactiveshell.py\", line 2047, in showtraceback\n",
      "    stb = self.InteractiveTB.structured_traceback(etype,\n",
      "  File \"/home/ubuntu/.local/lib/python3.8/site-packages/IPython/core/ultratb.py\", line 1436, in structured_traceback\n",
      "    return FormattedTB.structured_traceback(\n",
      "  File \"/home/ubuntu/.local/lib/python3.8/site-packages/IPython/core/ultratb.py\", line 1336, in structured_traceback\n",
      "    return VerboseTB.structured_traceback(\n",
      "  File \"/home/ubuntu/.local/lib/python3.8/site-packages/IPython/core/ultratb.py\", line 1193, in structured_traceback\n",
      "    formatted_exception = self.format_exception_as_a_whole(etype, evalue, etb, number_of_lines_of_context,\n",
      "  File \"/home/ubuntu/.local/lib/python3.8/site-packages/IPython/core/ultratb.py\", line 1151, in format_exception_as_a_whole\n",
      "    last_unique, recursion_repeat = find_recursion(orig_etype, evalue, records)\n",
      "  File \"/home/ubuntu/.local/lib/python3.8/site-packages/IPython/core/ultratb.py\", line 451, in find_recursion\n",
      "    return len(records), 0\n",
      "TypeError: object of type 'NoneType' has no len()\n",
      "\n",
      "During handling of the above exception, another exception occurred:\n",
      "\n",
      "Traceback (most recent call last):\n",
      "  File \"/home/ubuntu/.local/lib/python3.8/site-packages/IPython/core/interactiveshell.py\", line 2045, in showtraceback\n",
      "    stb = value._render_traceback_()\n",
      "AttributeError: 'TypeError' object has no attribute '_render_traceback_'\n",
      "\n",
      "During handling of the above exception, another exception occurred:\n",
      "\n",
      "Traceback (most recent call last):\n",
      "  File \"/home/ubuntu/.local/lib/python3.8/site-packages/IPython/core/ultratb.py\", line 1170, in get_records\n",
      "    return _fixed_getinnerframes(etb, number_of_lines_of_context, tb_offset)\n",
      "  File \"/home/ubuntu/.local/lib/python3.8/site-packages/IPython/core/ultratb.py\", line 316, in wrapped\n",
      "    return f(*args, **kwargs)\n",
      "  File \"/home/ubuntu/.local/lib/python3.8/site-packages/IPython/core/ultratb.py\", line 350, in _fixed_getinnerframes\n",
      "    records = fix_frame_records_filenames(inspect.getinnerframes(etb, context))\n",
      "  File \"/usr/lib/python3.8/inspect.py\", line 1503, in getinnerframes\n",
      "    frameinfo = (tb.tb_frame,) + getframeinfo(tb, context)\n",
      "  File \"/usr/lib/python3.8/inspect.py\", line 1461, in getframeinfo\n",
      "    filename = getsourcefile(frame) or getfile(frame)\n",
      "  File \"/usr/lib/python3.8/inspect.py\", line 708, in getsourcefile\n",
      "    if getattr(getmodule(object, filename), '__loader__', None) is not None:\n",
      "  File \"/usr/lib/python3.8/inspect.py\", line 737, in getmodule\n",
      "    file = getabsfile(object, _filename)\n",
      "  File \"/usr/lib/python3.8/inspect.py\", line 721, in getabsfile\n",
      "    return os.path.normcase(os.path.abspath(_filename))\n",
      "  File \"/usr/lib/python3.8/posixpath.py\", line 379, in abspath\n",
      "    cwd = os.getcwd()\n",
      "FileNotFoundError: [Errno 2] No such file or directory\n",
      "Traceback (most recent call last):\n",
      "  File \"/home/ubuntu/.local/lib/python3.8/site-packages/IPython/core/interactiveshell.py\", line 3418, in run_code\n",
      "    exec(code_obj, self.user_global_ns, self.user_ns)\n",
      "  File \"<ipython-input-12-80eb5ce7ce9f>\", line 1, in <module>\n",
      "    train_data_gen = train_image_generator.flow_from_directory(\n",
      "  File \"/home/ubuntu/.local/lib/python3.8/site-packages/tensorflow/python/keras/preprocessing/image.py\", line 943, in flow_from_directory\n",
      "    return DirectoryIterator(\n",
      "  File \"/home/ubuntu/.local/lib/python3.8/site-packages/tensorflow/python/keras/preprocessing/image.py\", line 381, in __init__\n",
      "    super(DirectoryIterator, self).__init__(\n",
      "  File \"/home/ubuntu/.local/lib/python3.8/site-packages/keras_preprocessing/image/directory_iterator.py\", line 115, in __init__\n",
      "    for subdir in sorted(os.listdir(directory)):\n",
      "FileNotFoundError: [Errno 2] No such file or directory: './dataset/train'\n",
      "\n",
      "During handling of the above exception, another exception occurred:\n",
      "\n",
      "Traceback (most recent call last):\n",
      "  File \"/home/ubuntu/.local/lib/python3.8/site-packages/IPython/core/interactiveshell.py\", line 2045, in showtraceback\n",
      "    stb = value._render_traceback_()\n",
      "AttributeError: 'FileNotFoundError' object has no attribute '_render_traceback_'\n",
      "\n",
      "During handling of the above exception, another exception occurred:\n",
      "\n",
      "Traceback (most recent call last):\n",
      "  File \"/home/ubuntu/.local/lib/python3.8/site-packages/IPython/core/interactiveshell.py\", line 3338, in run_ast_nodes\n",
      "    if (await self.run_code(code, result,  async_=asy)):\n",
      "  File \"/home/ubuntu/.local/lib/python3.8/site-packages/IPython/core/interactiveshell.py\", line 3435, in run_code\n",
      "    self.showtraceback(running_compiled_code=True)\n",
      "  File \"/home/ubuntu/.local/lib/python3.8/site-packages/IPython/core/interactiveshell.py\", line 2047, in showtraceback\n",
      "    stb = self.InteractiveTB.structured_traceback(etype,\n",
      "  File \"/home/ubuntu/.local/lib/python3.8/site-packages/IPython/core/ultratb.py\", line 1436, in structured_traceback\n",
      "    return FormattedTB.structured_traceback(\n",
      "  File \"/home/ubuntu/.local/lib/python3.8/site-packages/IPython/core/ultratb.py\", line 1336, in structured_traceback\n",
      "    return VerboseTB.structured_traceback(\n",
      "  File \"/home/ubuntu/.local/lib/python3.8/site-packages/IPython/core/ultratb.py\", line 1193, in structured_traceback\n",
      "    formatted_exception = self.format_exception_as_a_whole(etype, evalue, etb, number_of_lines_of_context,\n",
      "  File \"/home/ubuntu/.local/lib/python3.8/site-packages/IPython/core/ultratb.py\", line 1151, in format_exception_as_a_whole\n",
      "    last_unique, recursion_repeat = find_recursion(orig_etype, evalue, records)\n",
      "  File \"/home/ubuntu/.local/lib/python3.8/site-packages/IPython/core/ultratb.py\", line 451, in find_recursion\n",
      "    return len(records), 0\n",
      "TypeError: object of type 'NoneType' has no len()\n",
      "\n",
      "During handling of the above exception, another exception occurred:\n",
      "\n",
      "Traceback (most recent call last):\n",
      "  File \"/home/ubuntu/.local/lib/python3.8/site-packages/IPython/core/interactiveshell.py\", line 2045, in showtraceback\n",
      "    stb = value._render_traceback_()\n",
      "AttributeError: 'TypeError' object has no attribute '_render_traceback_'\n",
      "\n",
      "During handling of the above exception, another exception occurred:\n",
      "\n",
      "Traceback (most recent call last):\n",
      "  File \"/home/ubuntu/.local/lib/python3.8/site-packages/IPython/core/interactiveshell.py\", line 2923, in _run_cell\n",
      "    return runner(coro)\n",
      "  File \"/home/ubuntu/.local/lib/python3.8/site-packages/IPython/core/async_helpers.py\", line 68, in _pseudo_sync_runner\n",
      "    coro.send(None)\n",
      "  File \"/home/ubuntu/.local/lib/python3.8/site-packages/IPython/core/interactiveshell.py\", line 3146, in run_cell_async\n",
      "    has_raised = await self.run_ast_nodes(code_ast.body, cell_name,\n",
      "  File \"/home/ubuntu/.local/lib/python3.8/site-packages/IPython/core/interactiveshell.py\", line 3357, in run_ast_nodes\n",
      "    self.showtraceback()\n",
      "  File \"/home/ubuntu/.local/lib/python3.8/site-packages/IPython/core/interactiveshell.py\", line 2047, in showtraceback\n",
      "    stb = self.InteractiveTB.structured_traceback(etype,\n",
      "  File \"/home/ubuntu/.local/lib/python3.8/site-packages/IPython/core/ultratb.py\", line 1436, in structured_traceback\n",
      "    return FormattedTB.structured_traceback(\n",
      "  File \"/home/ubuntu/.local/lib/python3.8/site-packages/IPython/core/ultratb.py\", line 1336, in structured_traceback\n",
      "    return VerboseTB.structured_traceback(\n",
      "  File \"/home/ubuntu/.local/lib/python3.8/site-packages/IPython/core/ultratb.py\", line 1211, in structured_traceback\n",
      "    formatted_exceptions += self.format_exception_as_a_whole(etype, evalue, etb, lines_of_context,\n",
      "  File \"/home/ubuntu/.local/lib/python3.8/site-packages/IPython/core/ultratb.py\", line 1151, in format_exception_as_a_whole\n",
      "    last_unique, recursion_repeat = find_recursion(orig_etype, evalue, records)\n",
      "  File \"/home/ubuntu/.local/lib/python3.8/site-packages/IPython/core/ultratb.py\", line 451, in find_recursion\n",
      "    return len(records), 0\n",
      "TypeError: object of type 'NoneType' has no len()\n",
      "\n",
      "During handling of the above exception, another exception occurred:\n",
      "\n",
      "Traceback (most recent call last):\n",
      "  File \"/home/ubuntu/.local/lib/python3.8/site-packages/IPython/core/interactiveshell.py\", line 2045, in showtraceback\n",
      "    stb = value._render_traceback_()\n",
      "AttributeError: 'TypeError' object has no attribute '_render_traceback_'\n",
      "\n",
      "During handling of the above exception, another exception occurred:\n",
      "\n",
      "Traceback (most recent call last):\n",
      "  File \"/home/ubuntu/.local/lib/python3.8/site-packages/IPython/core/ultratb.py\", line 1170, in get_records\n",
      "    return _fixed_getinnerframes(etb, number_of_lines_of_context, tb_offset)\n",
      "  File \"/home/ubuntu/.local/lib/python3.8/site-packages/IPython/core/ultratb.py\", line 316, in wrapped\n",
      "    return f(*args, **kwargs)\n",
      "  File \"/home/ubuntu/.local/lib/python3.8/site-packages/IPython/core/ultratb.py\", line 350, in _fixed_getinnerframes\n",
      "    records = fix_frame_records_filenames(inspect.getinnerframes(etb, context))\n",
      "  File \"/usr/lib/python3.8/inspect.py\", line 1503, in getinnerframes\n",
      "    frameinfo = (tb.tb_frame,) + getframeinfo(tb, context)\n",
      "  File \"/usr/lib/python3.8/inspect.py\", line 1461, in getframeinfo\n",
      "    filename = getsourcefile(frame) or getfile(frame)\n",
      "  File \"/usr/lib/python3.8/inspect.py\", line 708, in getsourcefile\n",
      "    if getattr(getmodule(object, filename), '__loader__', None) is not None:\n",
      "  File \"/usr/lib/python3.8/inspect.py\", line 737, in getmodule\n",
      "    file = getabsfile(object, _filename)\n",
      "  File \"/usr/lib/python3.8/inspect.py\", line 721, in getabsfile\n",
      "    return os.path.normcase(os.path.abspath(_filename))\n",
      "  File \"/usr/lib/python3.8/posixpath.py\", line 379, in abspath\n",
      "    cwd = os.getcwd()\n",
      "FileNotFoundError: [Errno 2] No such file or directory\n"
     ]
    }
   ],
   "source": [
    "train_data_gen = train_image_generator.flow_from_directory(\n",
    "    batch_size = BATCH_SIZE,\n",
    "    directory = train_dir,\n",
    "    color_mode = 'grayscale',\n",
    "    shuffle = True,\n",
    "    target_size = (IMG_HEIGHT, IMG_WIDTH),\n",
    "    class_mode = 'categorical'\n",
    ")\n",
    "val_data_gen = validation_image_generator.flow_from_directory(\n",
    "    batch_size = BATCH_SIZE,\n",
    "    directory = validation_dir,\n",
    "    color_mode = 'grayscale',\n",
    "    shuffle = False,\n",
    "    target_size = (IMG_HEIGHT, IMG_WIDTH),\n",
    "    class_mode = 'categorical'\n",
    "  )"
   ]
  },
  {
   "cell_type": "code",
   "execution_count": null,
   "metadata": {
    "id": "dR7koc3fD9oF"
   },
   "outputs": [
    {
     "name": "stderr",
     "output_type": "stream",
     "text": [
      "ERROR:root:Internal Python error in the inspect module.\n",
      "Below is the traceback from this internal error.\n",
      "\n",
      "ERROR:root:Internal Python error in the inspect module.\n",
      "Below is the traceback from this internal error.\n",
      "\n",
      "ERROR:root:Internal Python error in the inspect module.\n",
      "Below is the traceback from this internal error.\n",
      "\n"
     ]
    },
    {
     "name": "stdout",
     "output_type": "stream",
     "text": [
      "Traceback (most recent call last):\n",
      "  File \"/home/ubuntu/.local/lib/python3.8/site-packages/IPython/core/interactiveshell.py\", line 3418, in run_code\n",
      "    exec(code_obj, self.user_global_ns, self.user_ns)\n",
      "  File \"<ipython-input-12-5021d7c90a80>\", line 10, in <module>\n",
      "    sample_training_images, _ = next(train_data_gen)\n",
      "NameError: name 'train_data_gen' is not defined\n",
      "\n",
      "During handling of the above exception, another exception occurred:\n",
      "\n",
      "Traceback (most recent call last):\n",
      "  File \"/home/ubuntu/.local/lib/python3.8/site-packages/IPython/core/interactiveshell.py\", line 2045, in showtraceback\n",
      "    stb = value._render_traceback_()\n",
      "AttributeError: 'NameError' object has no attribute '_render_traceback_'\n",
      "\n",
      "During handling of the above exception, another exception occurred:\n",
      "\n",
      "Traceback (most recent call last):\n",
      "  File \"/home/ubuntu/.local/lib/python3.8/site-packages/IPython/core/ultratb.py\", line 1170, in get_records\n",
      "    return _fixed_getinnerframes(etb, number_of_lines_of_context, tb_offset)\n",
      "  File \"/home/ubuntu/.local/lib/python3.8/site-packages/IPython/core/ultratb.py\", line 316, in wrapped\n",
      "    return f(*args, **kwargs)\n",
      "  File \"/home/ubuntu/.local/lib/python3.8/site-packages/IPython/core/ultratb.py\", line 350, in _fixed_getinnerframes\n",
      "    records = fix_frame_records_filenames(inspect.getinnerframes(etb, context))\n",
      "  File \"/usr/lib/python3.8/inspect.py\", line 1503, in getinnerframes\n",
      "    frameinfo = (tb.tb_frame,) + getframeinfo(tb, context)\n",
      "  File \"/usr/lib/python3.8/inspect.py\", line 1461, in getframeinfo\n",
      "    filename = getsourcefile(frame) or getfile(frame)\n",
      "  File \"/usr/lib/python3.8/inspect.py\", line 708, in getsourcefile\n",
      "    if getattr(getmodule(object, filename), '__loader__', None) is not None:\n",
      "  File \"/usr/lib/python3.8/inspect.py\", line 737, in getmodule\n",
      "    file = getabsfile(object, _filename)\n",
      "  File \"/usr/lib/python3.8/inspect.py\", line 721, in getabsfile\n",
      "    return os.path.normcase(os.path.abspath(_filename))\n",
      "  File \"/usr/lib/python3.8/posixpath.py\", line 379, in abspath\n",
      "    cwd = os.getcwd()\n",
      "FileNotFoundError: [Errno 2] No such file or directory\n",
      "ERROR! Session/line number was not unique in database. History logging moved to new session 27\n",
      "Traceback (most recent call last):\n",
      "  File \"/home/ubuntu/.local/lib/python3.8/site-packages/IPython/core/interactiveshell.py\", line 3418, in run_code\n",
      "    exec(code_obj, self.user_global_ns, self.user_ns)\n",
      "  File \"<ipython-input-12-5021d7c90a80>\", line 10, in <module>\n",
      "    sample_training_images, _ = next(train_data_gen)\n",
      "NameError: name 'train_data_gen' is not defined\n",
      "\n",
      "During handling of the above exception, another exception occurred:\n",
      "\n",
      "Traceback (most recent call last):\n",
      "  File \"/home/ubuntu/.local/lib/python3.8/site-packages/IPython/core/interactiveshell.py\", line 2045, in showtraceback\n",
      "    stb = value._render_traceback_()\n",
      "AttributeError: 'NameError' object has no attribute '_render_traceback_'\n",
      "\n",
      "During handling of the above exception, another exception occurred:\n",
      "\n",
      "Traceback (most recent call last):\n",
      "  File \"/home/ubuntu/.local/lib/python3.8/site-packages/IPython/core/interactiveshell.py\", line 3338, in run_ast_nodes\n",
      "    if (await self.run_code(code, result,  async_=asy)):\n",
      "  File \"/home/ubuntu/.local/lib/python3.8/site-packages/IPython/core/interactiveshell.py\", line 3435, in run_code\n",
      "    self.showtraceback(running_compiled_code=True)\n",
      "  File \"/home/ubuntu/.local/lib/python3.8/site-packages/IPython/core/interactiveshell.py\", line 2047, in showtraceback\n",
      "    stb = self.InteractiveTB.structured_traceback(etype,\n",
      "  File \"/home/ubuntu/.local/lib/python3.8/site-packages/IPython/core/ultratb.py\", line 1436, in structured_traceback\n",
      "    return FormattedTB.structured_traceback(\n",
      "  File \"/home/ubuntu/.local/lib/python3.8/site-packages/IPython/core/ultratb.py\", line 1336, in structured_traceback\n",
      "    return VerboseTB.structured_traceback(\n",
      "  File \"/home/ubuntu/.local/lib/python3.8/site-packages/IPython/core/ultratb.py\", line 1193, in structured_traceback\n",
      "    formatted_exception = self.format_exception_as_a_whole(etype, evalue, etb, number_of_lines_of_context,\n",
      "  File \"/home/ubuntu/.local/lib/python3.8/site-packages/IPython/core/ultratb.py\", line 1151, in format_exception_as_a_whole\n",
      "    last_unique, recursion_repeat = find_recursion(orig_etype, evalue, records)\n",
      "  File \"/home/ubuntu/.local/lib/python3.8/site-packages/IPython/core/ultratb.py\", line 451, in find_recursion\n",
      "    return len(records), 0\n",
      "TypeError: object of type 'NoneType' has no len()\n",
      "\n",
      "During handling of the above exception, another exception occurred:\n",
      "\n",
      "Traceback (most recent call last):\n",
      "  File \"/home/ubuntu/.local/lib/python3.8/site-packages/IPython/core/interactiveshell.py\", line 2045, in showtraceback\n",
      "    stb = value._render_traceback_()\n",
      "AttributeError: 'TypeError' object has no attribute '_render_traceback_'\n",
      "\n",
      "During handling of the above exception, another exception occurred:\n",
      "\n",
      "Traceback (most recent call last):\n",
      "  File \"/home/ubuntu/.local/lib/python3.8/site-packages/IPython/core/ultratb.py\", line 1170, in get_records\n",
      "    return _fixed_getinnerframes(etb, number_of_lines_of_context, tb_offset)\n",
      "  File \"/home/ubuntu/.local/lib/python3.8/site-packages/IPython/core/ultratb.py\", line 316, in wrapped\n",
      "    return f(*args, **kwargs)\n",
      "  File \"/home/ubuntu/.local/lib/python3.8/site-packages/IPython/core/ultratb.py\", line 350, in _fixed_getinnerframes\n",
      "    records = fix_frame_records_filenames(inspect.getinnerframes(etb, context))\n",
      "  File \"/usr/lib/python3.8/inspect.py\", line 1503, in getinnerframes\n",
      "    frameinfo = (tb.tb_frame,) + getframeinfo(tb, context)\n",
      "  File \"/usr/lib/python3.8/inspect.py\", line 1461, in getframeinfo\n",
      "    filename = getsourcefile(frame) or getfile(frame)\n",
      "  File \"/usr/lib/python3.8/inspect.py\", line 708, in getsourcefile\n",
      "    if getattr(getmodule(object, filename), '__loader__', None) is not None:\n",
      "  File \"/usr/lib/python3.8/inspect.py\", line 737, in getmodule\n",
      "    file = getabsfile(object, _filename)\n",
      "  File \"/usr/lib/python3.8/inspect.py\", line 721, in getabsfile\n",
      "    return os.path.normcase(os.path.abspath(_filename))\n",
      "  File \"/usr/lib/python3.8/posixpath.py\", line 379, in abspath\n",
      "    cwd = os.getcwd()\n",
      "FileNotFoundError: [Errno 2] No such file or directory\n",
      "Traceback (most recent call last):\n",
      "  File \"/home/ubuntu/.local/lib/python3.8/site-packages/IPython/core/interactiveshell.py\", line 3418, in run_code\n",
      "    exec(code_obj, self.user_global_ns, self.user_ns)\n",
      "  File \"<ipython-input-12-5021d7c90a80>\", line 10, in <module>\n",
      "    sample_training_images, _ = next(train_data_gen)\n",
      "NameError: name 'train_data_gen' is not defined\n",
      "\n",
      "During handling of the above exception, another exception occurred:\n",
      "\n",
      "Traceback (most recent call last):\n",
      "  File \"/home/ubuntu/.local/lib/python3.8/site-packages/IPython/core/interactiveshell.py\", line 2045, in showtraceback\n",
      "    stb = value._render_traceback_()\n",
      "AttributeError: 'NameError' object has no attribute '_render_traceback_'\n",
      "\n",
      "During handling of the above exception, another exception occurred:\n",
      "\n",
      "Traceback (most recent call last):\n",
      "  File \"/home/ubuntu/.local/lib/python3.8/site-packages/IPython/core/interactiveshell.py\", line 3338, in run_ast_nodes\n",
      "    if (await self.run_code(code, result,  async_=asy)):\n",
      "  File \"/home/ubuntu/.local/lib/python3.8/site-packages/IPython/core/interactiveshell.py\", line 3435, in run_code\n",
      "    self.showtraceback(running_compiled_code=True)\n",
      "  File \"/home/ubuntu/.local/lib/python3.8/site-packages/IPython/core/interactiveshell.py\", line 2047, in showtraceback\n",
      "    stb = self.InteractiveTB.structured_traceback(etype,\n",
      "  File \"/home/ubuntu/.local/lib/python3.8/site-packages/IPython/core/ultratb.py\", line 1436, in structured_traceback\n",
      "    return FormattedTB.structured_traceback(\n",
      "  File \"/home/ubuntu/.local/lib/python3.8/site-packages/IPython/core/ultratb.py\", line 1336, in structured_traceback\n",
      "    return VerboseTB.structured_traceback(\n",
      "  File \"/home/ubuntu/.local/lib/python3.8/site-packages/IPython/core/ultratb.py\", line 1193, in structured_traceback\n",
      "    formatted_exception = self.format_exception_as_a_whole(etype, evalue, etb, number_of_lines_of_context,\n",
      "  File \"/home/ubuntu/.local/lib/python3.8/site-packages/IPython/core/ultratb.py\", line 1151, in format_exception_as_a_whole\n",
      "    last_unique, recursion_repeat = find_recursion(orig_etype, evalue, records)\n",
      "  File \"/home/ubuntu/.local/lib/python3.8/site-packages/IPython/core/ultratb.py\", line 451, in find_recursion\n",
      "    return len(records), 0\n",
      "TypeError: object of type 'NoneType' has no len()\n",
      "\n",
      "During handling of the above exception, another exception occurred:\n",
      "\n",
      "Traceback (most recent call last):\n",
      "  File \"/home/ubuntu/.local/lib/python3.8/site-packages/IPython/core/interactiveshell.py\", line 2045, in showtraceback\n",
      "    stb = value._render_traceback_()\n",
      "AttributeError: 'TypeError' object has no attribute '_render_traceback_'\n",
      "\n",
      "During handling of the above exception, another exception occurred:\n",
      "\n",
      "Traceback (most recent call last):\n",
      "  File \"/home/ubuntu/.local/lib/python3.8/site-packages/IPython/core/interactiveshell.py\", line 2923, in _run_cell\n",
      "    return runner(coro)\n",
      "  File \"/home/ubuntu/.local/lib/python3.8/site-packages/IPython/core/async_helpers.py\", line 68, in _pseudo_sync_runner\n",
      "    coro.send(None)\n",
      "  File \"/home/ubuntu/.local/lib/python3.8/site-packages/IPython/core/interactiveshell.py\", line 3146, in run_cell_async\n",
      "    has_raised = await self.run_ast_nodes(code_ast.body, cell_name,\n",
      "  File \"/home/ubuntu/.local/lib/python3.8/site-packages/IPython/core/interactiveshell.py\", line 3357, in run_ast_nodes\n",
      "    self.showtraceback()\n",
      "  File \"/home/ubuntu/.local/lib/python3.8/site-packages/IPython/core/interactiveshell.py\", line 2047, in showtraceback\n",
      "    stb = self.InteractiveTB.structured_traceback(etype,\n",
      "  File \"/home/ubuntu/.local/lib/python3.8/site-packages/IPython/core/ultratb.py\", line 1436, in structured_traceback\n",
      "    return FormattedTB.structured_traceback(\n",
      "  File \"/home/ubuntu/.local/lib/python3.8/site-packages/IPython/core/ultratb.py\", line 1336, in structured_traceback\n",
      "    return VerboseTB.structured_traceback(\n",
      "  File \"/home/ubuntu/.local/lib/python3.8/site-packages/IPython/core/ultratb.py\", line 1211, in structured_traceback\n",
      "    formatted_exceptions += self.format_exception_as_a_whole(etype, evalue, etb, lines_of_context,\n",
      "  File \"/home/ubuntu/.local/lib/python3.8/site-packages/IPython/core/ultratb.py\", line 1151, in format_exception_as_a_whole\n",
      "    last_unique, recursion_repeat = find_recursion(orig_etype, evalue, records)\n",
      "  File \"/home/ubuntu/.local/lib/python3.8/site-packages/IPython/core/ultratb.py\", line 451, in find_recursion\n",
      "    return len(records), 0\n",
      "TypeError: object of type 'NoneType' has no len()\n",
      "\n",
      "During handling of the above exception, another exception occurred:\n",
      "\n",
      "Traceback (most recent call last):\n",
      "  File \"/home/ubuntu/.local/lib/python3.8/site-packages/IPython/core/interactiveshell.py\", line 2045, in showtraceback\n",
      "    stb = value._render_traceback_()\n",
      "AttributeError: 'TypeError' object has no attribute '_render_traceback_'\n",
      "\n",
      "During handling of the above exception, another exception occurred:\n",
      "\n",
      "Traceback (most recent call last):\n",
      "  File \"/home/ubuntu/.local/lib/python3.8/site-packages/IPython/core/ultratb.py\", line 1170, in get_records\n",
      "    return _fixed_getinnerframes(etb, number_of_lines_of_context, tb_offset)\n",
      "  File \"/home/ubuntu/.local/lib/python3.8/site-packages/IPython/core/ultratb.py\", line 316, in wrapped\n",
      "    return f(*args, **kwargs)\n",
      "  File \"/home/ubuntu/.local/lib/python3.8/site-packages/IPython/core/ultratb.py\", line 350, in _fixed_getinnerframes\n",
      "    records = fix_frame_records_filenames(inspect.getinnerframes(etb, context))\n",
      "  File \"/usr/lib/python3.8/inspect.py\", line 1503, in getinnerframes\n",
      "    frameinfo = (tb.tb_frame,) + getframeinfo(tb, context)\n",
      "  File \"/usr/lib/python3.8/inspect.py\", line 1461, in getframeinfo\n",
      "    filename = getsourcefile(frame) or getfile(frame)\n",
      "  File \"/usr/lib/python3.8/inspect.py\", line 708, in getsourcefile\n",
      "    if getattr(getmodule(object, filename), '__loader__', None) is not None:\n",
      "  File \"/usr/lib/python3.8/inspect.py\", line 737, in getmodule\n",
      "    file = getabsfile(object, _filename)\n",
      "  File \"/usr/lib/python3.8/inspect.py\", line 721, in getabsfile\n",
      "    return os.path.normcase(os.path.abspath(_filename))\n",
      "  File \"/usr/lib/python3.8/posixpath.py\", line 379, in abspath\n",
      "    cwd = os.getcwd()\n",
      "FileNotFoundError: [Errno 2] No such file or directory\n"
     ]
    }
   ],
   "source": [
    "def plotImages(images_arr):\n",
    "    fig, axes = plt.subplots(1, 5, figsize=(20,20))\n",
    "    axes = axes.flatten()\n",
    "    for img, ax in zip( images_arr, axes):\n",
    "        ax.imshow(img)\n",
    "        ax.axis('off')\n",
    "    plt.tight_layout()\n",
    "    plt.show()\n",
    "\n",
    "sample_training_images, _ = next(train_data_gen)\n",
    "plotImages(sample_training_images[:5])"
   ]
  },
  {
   "cell_type": "markdown",
   "metadata": {
    "id": "wGmwc97lOQip"
   },
   "source": [
    "## Define model"
   ]
  },
  {
   "cell_type": "code",
   "execution_count": 12,
   "metadata": {
    "colab": {
     "base_uri": "https://localhost:8080/"
    },
    "id": "yWxEUMxQEY0K",
    "outputId": "ec883933-c0f4-40c1-dfc7-ee60cb17aa2b"
   },
   "outputs": [
    {
     "name": "stdout",
     "output_type": "stream",
     "text": [
      "ERROR! Session/line number was not unique in database. History logging moved to new session 28\n",
      "Model: \"sequential_1\"\n",
      "_________________________________________________________________\n",
      "Layer (type)                 Output Shape              Param #   \n",
      "=================================================================\n",
      "conv2d_10 (Conv2D)           (None, 48, 48, 128)       3328      \n",
      "_________________________________________________________________\n",
      "conv2d_11 (Conv2D)           (None, 48, 48, 128)       409728    \n",
      "_________________________________________________________________\n",
      "batch_normalization_6 (Batch (None, 48, 48, 128)       512       \n",
      "_________________________________________________________________\n",
      "max_pooling2d_5 (MaxPooling2 (None, 24, 24, 128)       0         \n",
      "_________________________________________________________________\n",
      "dropout_6 (Dropout)          (None, 24, 24, 128)       0         \n",
      "_________________________________________________________________\n",
      "conv2d_12 (Conv2D)           (None, 24, 24, 128)       409728    \n",
      "_________________________________________________________________\n",
      "conv2d_13 (Conv2D)           (None, 24, 24, 128)       409728    \n",
      "_________________________________________________________________\n",
      "batch_normalization_7 (Batch (None, 24, 24, 128)       512       \n",
      "_________________________________________________________________\n",
      "max_pooling2d_6 (MaxPooling2 (None, 12, 12, 128)       0         \n",
      "_________________________________________________________________\n",
      "dropout_7 (Dropout)          (None, 12, 12, 128)       0         \n",
      "_________________________________________________________________\n",
      "conv2d_14 (Conv2D)           (None, 12, 12, 128)       409728    \n",
      "_________________________________________________________________\n",
      "conv2d_15 (Conv2D)           (None, 12, 12, 128)       409728    \n",
      "_________________________________________________________________\n",
      "batch_normalization_8 (Batch (None, 12, 12, 128)       512       \n",
      "_________________________________________________________________\n",
      "max_pooling2d_7 (MaxPooling2 (None, 6, 6, 128)         0         \n",
      "_________________________________________________________________\n",
      "dropout_8 (Dropout)          (None, 6, 6, 128)         0         \n",
      "_________________________________________________________________\n",
      "conv2d_16 (Conv2D)           (None, 6, 6, 128)         409728    \n",
      "_________________________________________________________________\n",
      "conv2d_17 (Conv2D)           (None, 6, 6, 128)         409728    \n",
      "_________________________________________________________________\n",
      "batch_normalization_9 (Batch (None, 6, 6, 128)         512       \n",
      "_________________________________________________________________\n",
      "max_pooling2d_8 (MaxPooling2 (None, 3, 3, 128)         0         \n",
      "_________________________________________________________________\n",
      "dropout_9 (Dropout)          (None, 3, 3, 128)         0         \n",
      "_________________________________________________________________\n",
      "conv2d_18 (Conv2D)           (None, 3, 3, 128)         147584    \n",
      "_________________________________________________________________\n",
      "conv2d_19 (Conv2D)           (None, 3, 3, 128)         147584    \n",
      "_________________________________________________________________\n",
      "batch_normalization_10 (Batc (None, 3, 3, 128)         512       \n",
      "_________________________________________________________________\n",
      "max_pooling2d_9 (MaxPooling2 (None, 1, 1, 128)         0         \n",
      "_________________________________________________________________\n",
      "dropout_10 (Dropout)         (None, 1, 1, 128)         0         \n",
      "_________________________________________________________________\n",
      "flatten_1 (Flatten)          (None, 128)               0         \n",
      "_________________________________________________________________\n",
      "dense_2 (Dense)              (None, 1024)              132096    \n",
      "_________________________________________________________________\n",
      "batch_normalization_11 (Batc (None, 1024)              4096      \n",
      "_________________________________________________________________\n",
      "activation_2 (Activation)    (None, 1024)              0         \n",
      "_________________________________________________________________\n",
      "dropout_11 (Dropout)         (None, 1024)              0         \n",
      "_________________________________________________________________\n",
      "dense_3 (Dense)              (None, 5)                 5125      \n",
      "_________________________________________________________________\n",
      "activation_3 (Activation)    (None, 5)                 0         \n",
      "=================================================================\n",
      "Total params: 3,310,469\n",
      "Trainable params: 3,307,141\n",
      "Non-trainable params: 3,328\n",
      "_________________________________________________________________\n"
     ]
    }
   ],
   "source": [
    "def simple_cnn():\n",
    "  model = Sequential()\n",
    "  input_shape = (IMG_HEIGHT, IMG_WIDTH, 1)\n",
    "  model.add(Conv2D(128, (5, 5), input_shape=input_shape, activation='relu', padding='same', kernel_regularizer = regularizers.l2(L2_WEIGHT_DECAY)))\n",
    "  model.add(Conv2D(128, (5, 5), activation='relu', padding='same', kernel_regularizer = regularizers.l2(L2_WEIGHT_DECAY)))\n",
    "  model.add(BatchNormalization())\n",
    "  model.add(MaxPooling2D(pool_size=(2, 2)))\n",
    "  model.add(Dropout(DROPOUT_RATE))\n",
    "\n",
    "  model.add(Conv2D(128, (5, 5),activation='relu',padding='same', kernel_regularizer = regularizers.l2(L2_WEIGHT_DECAY)))\n",
    "  model.add(Conv2D(128, (5, 5),activation='relu',padding='same', kernel_regularizer = regularizers.l2(L2_WEIGHT_DECAY)))\n",
    "  model.add(BatchNormalization())\n",
    "  model.add(MaxPooling2D(pool_size=(2, 2)))\n",
    "  model.add(Dropout(DROPOUT_RATE))\n",
    "\n",
    "  model.add(Conv2D(128, (5, 5),activation='relu',padding='same', kernel_regularizer = regularizers.l2(L2_WEIGHT_DECAY)))\n",
    "  model.add(Conv2D(128, (5, 5),activation='relu',padding='same', kernel_regularizer = regularizers.l2(L2_WEIGHT_DECAY)))\n",
    "  model.add(BatchNormalization())\n",
    "  model.add(MaxPooling2D(pool_size=(2, 2)))\n",
    "  model.add(Dropout(DROPOUT_RATE))\n",
    "\n",
    "  model.add(Conv2D(128, (5, 5),activation='relu',padding='same', kernel_regularizer = regularizers.l2(L2_WEIGHT_DECAY)))\n",
    "  model.add(Conv2D(128, (5, 5),activation='relu',padding='same', kernel_regularizer = regularizers.l2(L2_WEIGHT_DECAY)))\n",
    "  model.add(BatchNormalization())\n",
    "  model.add(MaxPooling2D(pool_size=(2, 2)))\n",
    "  model.add(Dropout(DROPOUT_RATE))\n",
    "\n",
    "  model.add(Conv2D(128, (3, 3),activation='relu',padding='same', kernel_regularizer = regularizers.l2(L2_WEIGHT_DECAY)))\n",
    "  model.add(Conv2D(128, (3, 3),activation='relu',padding='same', kernel_regularizer = regularizers.l2(L2_WEIGHT_DECAY)))\n",
    "  model.add(BatchNormalization())\n",
    "  model.add(MaxPooling2D(pool_size=(2, 2)))\n",
    "  model.add(Dropout(DROPOUT_RATE))\n",
    "\n",
    "  model.add(Flatten())\n",
    "  model.add(Dense(1024))\n",
    "  model.add(BatchNormalization())\n",
    "  model.add(Activation('relu'))\n",
    "  model.add(Dropout(DROPOUT_RATE))\n",
    "  model.add(Dense(NUM_OUTPUTS, activation=\"softmax\"))\n",
    "  model.add(Activation('softmax'))\n",
    "  return model\n",
    "\n",
    "def resnet_fine_tuning():\n",
    "  base_model = ResNet50(weights='imagenet', include_top=False, input_shape = (IMG_HEIGHT, IMG_WIDTH, 3))\n",
    "  x = base_model.output\n",
    "  x = GlobalAveragePooling2D()(x)\n",
    "  x = Flatten()(x)\n",
    "  x = Dense(1024, activation='relu')(x)\n",
    "  x = Dense(NUM_OUTPUTS, activation='softmax')(x)\n",
    "  model = Model(inputs=base_model.input, outputs=x)\n",
    "  return model\n",
    "\n",
    "model = simple_cnn()\n",
    "# model = resnet_fine_tuning()\n",
    "\n",
    "optimizer = Adam(lr = LEARNING_RATE, beta_1 = 0.9, beta_2 = 0.999, epsilon = 1e-7)\n",
    "model.compile(loss='categorical_crossentropy', metrics=['accuracy'], optimizer = optimizer)\n",
    "model.summary()"
   ]
  },
  {
   "cell_type": "markdown",
   "metadata": {
    "id": "wGmwc97lOQip"
   },
   "source": [
    "## Train model"
   ]
  },
  {
   "cell_type": "code",
   "execution_count": null,
   "metadata": {
    "colab": {
     "base_uri": "https://localhost:8080/"
    },
    "id": "TnDrZaNYI0-f",
    "outputId": "e949fa2a-ec53-4fe3-a0ca-cacedbd85e20"
   },
   "outputs": [
    {
     "name": "stderr",
     "output_type": "stream",
     "text": [
      "ERROR:root:Internal Python error in the inspect module.\n",
      "Below is the traceback from this internal error.\n",
      "\n",
      "ERROR:root:Internal Python error in the inspect module.\n",
      "Below is the traceback from this internal error.\n",
      "\n"
     ]
    },
    {
     "name": "stdout",
     "output_type": "stream",
     "text": [
      "Traceback (most recent call last):\n",
      "  File \"/home/ubuntu/.local/lib/python3.8/site-packages/IPython/core/interactiveshell.py\", line 3418, in run_code\n",
      "    exec(code_obj, self.user_global_ns, self.user_ns)\n",
      "  File \"<ipython-input-13-128d7dc75674>\", line 18, in <module>\n",
      "    train_data_gen,\n",
      "NameError: name 'train_data_gen' is not defined\n",
      "\n",
      "During handling of the above exception, another exception occurred:\n",
      "\n",
      "Traceback (most recent call last):\n",
      "  File \"/home/ubuntu/.local/lib/python3.8/site-packages/IPython/core/interactiveshell.py\", line 2045, in showtraceback\n",
      "    stb = value._render_traceback_()\n",
      "AttributeError: 'NameError' object has no attribute '_render_traceback_'\n",
      "\n",
      "During handling of the above exception, another exception occurred:\n",
      "\n",
      "Traceback (most recent call last):\n",
      "  File \"/home/ubuntu/.local/lib/python3.8/site-packages/IPython/core/ultratb.py\", line 1170, in get_records\n",
      "    return _fixed_getinnerframes(etb, number_of_lines_of_context, tb_offset)\n",
      "  File \"/home/ubuntu/.local/lib/python3.8/site-packages/IPython/core/ultratb.py\", line 316, in wrapped\n",
      "    return f(*args, **kwargs)\n",
      "  File \"/home/ubuntu/.local/lib/python3.8/site-packages/IPython/core/ultratb.py\", line 350, in _fixed_getinnerframes\n",
      "    records = fix_frame_records_filenames(inspect.getinnerframes(etb, context))\n",
      "  File \"/usr/lib/python3.8/inspect.py\", line 1503, in getinnerframes\n",
      "    frameinfo = (tb.tb_frame,) + getframeinfo(tb, context)\n",
      "  File \"/usr/lib/python3.8/inspect.py\", line 1461, in getframeinfo\n",
      "    filename = getsourcefile(frame) or getfile(frame)\n",
      "  File \"/usr/lib/python3.8/inspect.py\", line 708, in getsourcefile\n",
      "    if getattr(getmodule(object, filename), '__loader__', None) is not None:\n",
      "  File \"/usr/lib/python3.8/inspect.py\", line 737, in getmodule\n",
      "    file = getabsfile(object, _filename)\n",
      "  File \"/usr/lib/python3.8/inspect.py\", line 721, in getabsfile\n",
      "    return os.path.normcase(os.path.abspath(_filename))\n",
      "  File \"/usr/lib/python3.8/posixpath.py\", line 379, in abspath\n",
      "    cwd = os.getcwd()\n",
      "FileNotFoundError: [Errno 2] No such file or directory\n",
      "Traceback (most recent call last):\n",
      "  File \"/home/ubuntu/.local/lib/python3.8/site-packages/IPython/core/interactiveshell.py\", line 3418, in run_code\n",
      "    exec(code_obj, self.user_global_ns, self.user_ns)\n",
      "  File \"<ipython-input-13-128d7dc75674>\", line 18, in <module>\n",
      "    train_data_gen,\n",
      "NameError: name 'train_data_gen' is not defined\n",
      "\n",
      "During handling of the above exception, another exception occurred:\n",
      "\n",
      "Traceback (most recent call last):\n",
      "  File \"/home/ubuntu/.local/lib/python3.8/site-packages/IPython/core/interactiveshell.py\", line 2045, in showtraceback\n",
      "    stb = value._render_traceback_()\n",
      "AttributeError: 'NameError' object has no attribute '_render_traceback_'\n",
      "\n",
      "During handling of the above exception, another exception occurred:\n",
      "\n",
      "Traceback (most recent call last):\n",
      "  File \"/home/ubuntu/.local/lib/python3.8/site-packages/IPython/core/interactiveshell.py\", line 3338, in run_ast_nodes\n",
      "    if (await self.run_code(code, result,  async_=asy)):\n",
      "  File \"/home/ubuntu/.local/lib/python3.8/site-packages/IPython/core/interactiveshell.py\", line 3435, in run_code\n",
      "    self.showtraceback(running_compiled_code=True)\n",
      "  File \"/home/ubuntu/.local/lib/python3.8/site-packages/IPython/core/interactiveshell.py\", line 2047, in showtraceback\n",
      "    stb = self.InteractiveTB.structured_traceback(etype,\n",
      "  File \"/home/ubuntu/.local/lib/python3.8/site-packages/IPython/core/ultratb.py\", line 1436, in structured_traceback\n",
      "    return FormattedTB.structured_traceback(\n",
      "  File \"/home/ubuntu/.local/lib/python3.8/site-packages/IPython/core/ultratb.py\", line 1336, in structured_traceback\n",
      "    return VerboseTB.structured_traceback(\n",
      "  File \"/home/ubuntu/.local/lib/python3.8/site-packages/IPython/core/ultratb.py\", line 1193, in structured_traceback\n",
      "    formatted_exception = self.format_exception_as_a_whole(etype, evalue, etb, number_of_lines_of_context,\n",
      "  File \"/home/ubuntu/.local/lib/python3.8/site-packages/IPython/core/ultratb.py\", line 1151, in format_exception_as_a_whole\n",
      "    last_unique, recursion_repeat = find_recursion(orig_etype, evalue, records)\n",
      "  File \"/home/ubuntu/.local/lib/python3.8/site-packages/IPython/core/ultratb.py\", line 451, in find_recursion\n",
      "    return len(records), 0\n",
      "TypeError: object of type 'NoneType' has no len()\n",
      "\n",
      "During handling of the above exception, another exception occurred:\n",
      "\n",
      "Traceback (most recent call last):\n",
      "  File \"/home/ubuntu/.local/lib/python3.8/site-packages/IPython/core/interactiveshell.py\", line 2045, in showtraceback\n",
      "    stb = value._render_traceback_()\n",
      "AttributeError: 'TypeError' object has no attribute '_render_traceback_'\n",
      "\n",
      "During handling of the above exception, another exception occurred:\n",
      "\n",
      "Traceback (most recent call last):\n",
      "  File \"/home/ubuntu/.local/lib/python3.8/site-packages/IPython/core/ultratb.py\", line 1170, in get_records\n",
      "    return _fixed_getinnerframes(etb, number_of_lines_of_context, tb_offset)\n",
      "  File \"/home/ubuntu/.local/lib/python3.8/site-packages/IPython/core/ultratb.py\", line 316, in wrapped\n",
      "    return f(*args, **kwargs)\n",
      "  File \"/home/ubuntu/.local/lib/python3.8/site-packages/IPython/core/ultratb.py\", line 350, in _fixed_getinnerframes\n",
      "    records = fix_frame_records_filenames(inspect.getinnerframes(etb, context))\n",
      "  File \"/usr/lib/python3.8/inspect.py\", line 1503, in getinnerframes\n",
      "    frameinfo = (tb.tb_frame,) + getframeinfo(tb, context)\n",
      "  File \"/usr/lib/python3.8/inspect.py\", line 1461, in getframeinfo\n",
      "    filename = getsourcefile(frame) or getfile(frame)\n",
      "  File \"/usr/lib/python3.8/inspect.py\", line 708, in getsourcefile\n",
      "    if getattr(getmodule(object, filename), '__loader__', None) is not None:\n",
      "  File \"/usr/lib/python3.8/inspect.py\", line 737, in getmodule\n",
      "    file = getabsfile(object, _filename)\n",
      "  File \"/usr/lib/python3.8/inspect.py\", line 721, in getabsfile\n",
      "    return os.path.normcase(os.path.abspath(_filename))\n",
      "  File \"/usr/lib/python3.8/posixpath.py\", line 379, in abspath\n",
      "    cwd = os.getcwd()\n",
      "FileNotFoundError: [Errno 2] No such file or directory\n"
     ]
    },
    {
     "name": "stderr",
     "output_type": "stream",
     "text": [
      "ERROR:root:Internal Python error in the inspect module.\n",
      "Below is the traceback from this internal error.\n",
      "\n"
     ]
    },
    {
     "name": "stdout",
     "output_type": "stream",
     "text": [
      "Traceback (most recent call last):\n",
      "  File \"/home/ubuntu/.local/lib/python3.8/site-packages/IPython/core/interactiveshell.py\", line 3418, in run_code\n",
      "    exec(code_obj, self.user_global_ns, self.user_ns)\n",
      "  File \"<ipython-input-13-128d7dc75674>\", line 18, in <module>\n",
      "    train_data_gen,\n",
      "NameError: name 'train_data_gen' is not defined\n",
      "\n",
      "During handling of the above exception, another exception occurred:\n",
      "\n",
      "Traceback (most recent call last):\n",
      "  File \"/home/ubuntu/.local/lib/python3.8/site-packages/IPython/core/interactiveshell.py\", line 2045, in showtraceback\n",
      "    stb = value._render_traceback_()\n",
      "AttributeError: 'NameError' object has no attribute '_render_traceback_'\n",
      "\n",
      "During handling of the above exception, another exception occurred:\n",
      "\n",
      "Traceback (most recent call last):\n",
      "  File \"/home/ubuntu/.local/lib/python3.8/site-packages/IPython/core/interactiveshell.py\", line 3338, in run_ast_nodes\n",
      "    if (await self.run_code(code, result,  async_=asy)):\n",
      "  File \"/home/ubuntu/.local/lib/python3.8/site-packages/IPython/core/interactiveshell.py\", line 3435, in run_code\n",
      "    self.showtraceback(running_compiled_code=True)\n",
      "  File \"/home/ubuntu/.local/lib/python3.8/site-packages/IPython/core/interactiveshell.py\", line 2047, in showtraceback\n",
      "    stb = self.InteractiveTB.structured_traceback(etype,\n",
      "  File \"/home/ubuntu/.local/lib/python3.8/site-packages/IPython/core/ultratb.py\", line 1436, in structured_traceback\n",
      "    return FormattedTB.structured_traceback(\n",
      "  File \"/home/ubuntu/.local/lib/python3.8/site-packages/IPython/core/ultratb.py\", line 1336, in structured_traceback\n",
      "    return VerboseTB.structured_traceback(\n",
      "  File \"/home/ubuntu/.local/lib/python3.8/site-packages/IPython/core/ultratb.py\", line 1193, in structured_traceback\n",
      "    formatted_exception = self.format_exception_as_a_whole(etype, evalue, etb, number_of_lines_of_context,\n",
      "  File \"/home/ubuntu/.local/lib/python3.8/site-packages/IPython/core/ultratb.py\", line 1151, in format_exception_as_a_whole\n",
      "    last_unique, recursion_repeat = find_recursion(orig_etype, evalue, records)\n",
      "  File \"/home/ubuntu/.local/lib/python3.8/site-packages/IPython/core/ultratb.py\", line 451, in find_recursion\n",
      "    return len(records), 0\n",
      "TypeError: object of type 'NoneType' has no len()\n",
      "\n",
      "During handling of the above exception, another exception occurred:\n",
      "\n",
      "Traceback (most recent call last):\n",
      "  File \"/home/ubuntu/.local/lib/python3.8/site-packages/IPython/core/interactiveshell.py\", line 2045, in showtraceback\n",
      "    stb = value._render_traceback_()\n",
      "AttributeError: 'TypeError' object has no attribute '_render_traceback_'\n",
      "\n",
      "During handling of the above exception, another exception occurred:\n",
      "\n",
      "Traceback (most recent call last):\n",
      "  File \"/home/ubuntu/.local/lib/python3.8/site-packages/IPython/core/interactiveshell.py\", line 2923, in _run_cell\n",
      "    return runner(coro)\n",
      "  File \"/home/ubuntu/.local/lib/python3.8/site-packages/IPython/core/async_helpers.py\", line 68, in _pseudo_sync_runner\n",
      "    coro.send(None)\n",
      "  File \"/home/ubuntu/.local/lib/python3.8/site-packages/IPython/core/interactiveshell.py\", line 3146, in run_cell_async\n",
      "    has_raised = await self.run_ast_nodes(code_ast.body, cell_name,\n",
      "  File \"/home/ubuntu/.local/lib/python3.8/site-packages/IPython/core/interactiveshell.py\", line 3357, in run_ast_nodes\n",
      "    self.showtraceback()\n",
      "  File \"/home/ubuntu/.local/lib/python3.8/site-packages/IPython/core/interactiveshell.py\", line 2047, in showtraceback\n",
      "    stb = self.InteractiveTB.structured_traceback(etype,\n",
      "  File \"/home/ubuntu/.local/lib/python3.8/site-packages/IPython/core/ultratb.py\", line 1436, in structured_traceback\n",
      "    return FormattedTB.structured_traceback(\n",
      "  File \"/home/ubuntu/.local/lib/python3.8/site-packages/IPython/core/ultratb.py\", line 1336, in structured_traceback\n",
      "    return VerboseTB.structured_traceback(\n",
      "  File \"/home/ubuntu/.local/lib/python3.8/site-packages/IPython/core/ultratb.py\", line 1211, in structured_traceback\n",
      "    formatted_exceptions += self.format_exception_as_a_whole(etype, evalue, etb, lines_of_context,\n",
      "  File \"/home/ubuntu/.local/lib/python3.8/site-packages/IPython/core/ultratb.py\", line 1151, in format_exception_as_a_whole\n",
      "    last_unique, recursion_repeat = find_recursion(orig_etype, evalue, records)\n",
      "  File \"/home/ubuntu/.local/lib/python3.8/site-packages/IPython/core/ultratb.py\", line 451, in find_recursion\n",
      "    return len(records), 0\n",
      "TypeError: object of type 'NoneType' has no len()\n",
      "\n",
      "During handling of the above exception, another exception occurred:\n",
      "\n",
      "Traceback (most recent call last):\n",
      "  File \"/home/ubuntu/.local/lib/python3.8/site-packages/IPython/core/interactiveshell.py\", line 2045, in showtraceback\n",
      "    stb = value._render_traceback_()\n",
      "AttributeError: 'TypeError' object has no attribute '_render_traceback_'\n",
      "\n",
      "During handling of the above exception, another exception occurred:\n",
      "\n",
      "Traceback (most recent call last):\n",
      "  File \"/home/ubuntu/.local/lib/python3.8/site-packages/IPython/core/ultratb.py\", line 1170, in get_records\n",
      "    return _fixed_getinnerframes(etb, number_of_lines_of_context, tb_offset)\n",
      "  File \"/home/ubuntu/.local/lib/python3.8/site-packages/IPython/core/ultratb.py\", line 316, in wrapped\n",
      "    return f(*args, **kwargs)\n",
      "  File \"/home/ubuntu/.local/lib/python3.8/site-packages/IPython/core/ultratb.py\", line 350, in _fixed_getinnerframes\n",
      "    records = fix_frame_records_filenames(inspect.getinnerframes(etb, context))\n",
      "  File \"/usr/lib/python3.8/inspect.py\", line 1503, in getinnerframes\n",
      "    frameinfo = (tb.tb_frame,) + getframeinfo(tb, context)\n",
      "  File \"/usr/lib/python3.8/inspect.py\", line 1461, in getframeinfo\n",
      "    filename = getsourcefile(frame) or getfile(frame)\n",
      "  File \"/usr/lib/python3.8/inspect.py\", line 708, in getsourcefile\n",
      "    if getattr(getmodule(object, filename), '__loader__', None) is not None:\n",
      "  File \"/usr/lib/python3.8/inspect.py\", line 737, in getmodule\n",
      "    file = getabsfile(object, _filename)\n",
      "  File \"/usr/lib/python3.8/inspect.py\", line 721, in getabsfile\n",
      "    return os.path.normcase(os.path.abspath(_filename))\n",
      "  File \"/usr/lib/python3.8/posixpath.py\", line 379, in abspath\n",
      "    cwd = os.getcwd()\n",
      "FileNotFoundError: [Errno 2] No such file or directory\n"
     ]
    }
   ],
   "source": [
    "# from google.colab import drive\n",
    "# drive.mount(\"/content/gdrive\", force_remount = False)\n",
    "\n",
    "# def get_drive_path():\n",
    "#   path = F\"/content/gdrive/MyDrive/Colab Notebooks/weights/\"\n",
    "#   path += \"weights_{epoch:02d}_{accuracy:.4f}_{val_accuracy:.4f}.h5\"\n",
    "#   return path\n",
    "\n",
    "def get_local_path():\n",
    "  path = os.path.join(\"weights/\", \"weights_{epoch:02d}_{accuracy:.4f}_{val_accuracy:.4f}.h5\")\n",
    "  return path\n",
    "\n",
    "# path = get_drive_path()\n",
    "path = get_local_path()\n",
    "save_model_callback = ModelCheckpoint(filepath = path)\n",
    "\n",
    "history = model.fit(\n",
    "    train_data_gen,\n",
    "    steps_per_epoch = total_train // BATCH_SIZE,\n",
    "    epochs = EPOCHS,\n",
    "    validation_data = val_data_gen,\n",
    "    validation_steps = total_val // BATCH_SIZE,\n",
    "    callbacks = [save_model_callback]\n",
    ")"
   ]
  },
  {
   "cell_type": "markdown",
   "metadata": {
    "id": "9ubmRJLrk_45"
   },
   "source": [
    "## Plot training result"
   ]
  },
  {
   "cell_type": "code",
   "execution_count": null,
   "metadata": {
    "id": "M1aOJQnqJG_6"
   },
   "outputs": [
    {
     "name": "stderr",
     "output_type": "stream",
     "text": [
      "ERROR:root:Internal Python error in the inspect module.\n",
      "Below is the traceback from this internal error.\n",
      "\n",
      "ERROR:root:Internal Python error in the inspect module.\n",
      "Below is the traceback from this internal error.\n",
      "\n",
      "ERROR:root:Internal Python error in the inspect module.\n",
      "Below is the traceback from this internal error.\n",
      "\n"
     ]
    },
    {
     "name": "stdout",
     "output_type": "stream",
     "text": [
      "Traceback (most recent call last):\n",
      "  File \"/home/ubuntu/.local/lib/python3.8/site-packages/IPython/core/interactiveshell.py\", line 3418, in run_code\n",
      "    exec(code_obj, self.user_global_ns, self.user_ns)\n",
      "  File \"<ipython-input-13-97ade24e7925>\", line 1, in <module>\n",
      "    acc = history.history['accuracy']\n",
      "NameError: name 'history' is not defined\n",
      "\n",
      "During handling of the above exception, another exception occurred:\n",
      "\n",
      "Traceback (most recent call last):\n",
      "  File \"/home/ubuntu/.local/lib/python3.8/site-packages/IPython/core/interactiveshell.py\", line 2045, in showtraceback\n",
      "    stb = value._render_traceback_()\n",
      "AttributeError: 'NameError' object has no attribute '_render_traceback_'\n",
      "\n",
      "During handling of the above exception, another exception occurred:\n",
      "\n",
      "Traceback (most recent call last):\n",
      "  File \"/home/ubuntu/.local/lib/python3.8/site-packages/IPython/core/ultratb.py\", line 1170, in get_records\n",
      "    return _fixed_getinnerframes(etb, number_of_lines_of_context, tb_offset)\n",
      "  File \"/home/ubuntu/.local/lib/python3.8/site-packages/IPython/core/ultratb.py\", line 316, in wrapped\n",
      "    return f(*args, **kwargs)\n",
      "  File \"/home/ubuntu/.local/lib/python3.8/site-packages/IPython/core/ultratb.py\", line 350, in _fixed_getinnerframes\n",
      "    records = fix_frame_records_filenames(inspect.getinnerframes(etb, context))\n",
      "  File \"/usr/lib/python3.8/inspect.py\", line 1503, in getinnerframes\n",
      "    frameinfo = (tb.tb_frame,) + getframeinfo(tb, context)\n",
      "  File \"/usr/lib/python3.8/inspect.py\", line 1461, in getframeinfo\n",
      "    filename = getsourcefile(frame) or getfile(frame)\n",
      "  File \"/usr/lib/python3.8/inspect.py\", line 708, in getsourcefile\n",
      "    if getattr(getmodule(object, filename), '__loader__', None) is not None:\n",
      "  File \"/usr/lib/python3.8/inspect.py\", line 737, in getmodule\n",
      "    file = getabsfile(object, _filename)\n",
      "  File \"/usr/lib/python3.8/inspect.py\", line 721, in getabsfile\n",
      "    return os.path.normcase(os.path.abspath(_filename))\n",
      "  File \"/usr/lib/python3.8/posixpath.py\", line 379, in abspath\n",
      "    cwd = os.getcwd()\n",
      "FileNotFoundError: [Errno 2] No such file or directory\n",
      "ERROR! Session/line number was not unique in database. History logging moved to new session 29\n",
      "Traceback (most recent call last):\n",
      "  File \"/home/ubuntu/.local/lib/python3.8/site-packages/IPython/core/interactiveshell.py\", line 3418, in run_code\n",
      "    exec(code_obj, self.user_global_ns, self.user_ns)\n",
      "  File \"<ipython-input-13-97ade24e7925>\", line 1, in <module>\n",
      "    acc = history.history['accuracy']\n",
      "NameError: name 'history' is not defined\n",
      "\n",
      "During handling of the above exception, another exception occurred:\n",
      "\n",
      "Traceback (most recent call last):\n",
      "  File \"/home/ubuntu/.local/lib/python3.8/site-packages/IPython/core/interactiveshell.py\", line 2045, in showtraceback\n",
      "    stb = value._render_traceback_()\n",
      "AttributeError: 'NameError' object has no attribute '_render_traceback_'\n",
      "\n",
      "During handling of the above exception, another exception occurred:\n",
      "\n",
      "Traceback (most recent call last):\n",
      "  File \"/home/ubuntu/.local/lib/python3.8/site-packages/IPython/core/interactiveshell.py\", line 3338, in run_ast_nodes\n",
      "    if (await self.run_code(code, result,  async_=asy)):\n",
      "  File \"/home/ubuntu/.local/lib/python3.8/site-packages/IPython/core/interactiveshell.py\", line 3435, in run_code\n",
      "    self.showtraceback(running_compiled_code=True)\n",
      "  File \"/home/ubuntu/.local/lib/python3.8/site-packages/IPython/core/interactiveshell.py\", line 2047, in showtraceback\n",
      "    stb = self.InteractiveTB.structured_traceback(etype,\n",
      "  File \"/home/ubuntu/.local/lib/python3.8/site-packages/IPython/core/ultratb.py\", line 1436, in structured_traceback\n",
      "    return FormattedTB.structured_traceback(\n",
      "  File \"/home/ubuntu/.local/lib/python3.8/site-packages/IPython/core/ultratb.py\", line 1336, in structured_traceback\n",
      "    return VerboseTB.structured_traceback(\n",
      "  File \"/home/ubuntu/.local/lib/python3.8/site-packages/IPython/core/ultratb.py\", line 1193, in structured_traceback\n",
      "    formatted_exception = self.format_exception_as_a_whole(etype, evalue, etb, number_of_lines_of_context,\n",
      "  File \"/home/ubuntu/.local/lib/python3.8/site-packages/IPython/core/ultratb.py\", line 1151, in format_exception_as_a_whole\n",
      "    last_unique, recursion_repeat = find_recursion(orig_etype, evalue, records)\n",
      "  File \"/home/ubuntu/.local/lib/python3.8/site-packages/IPython/core/ultratb.py\", line 451, in find_recursion\n",
      "    return len(records), 0\n",
      "TypeError: object of type 'NoneType' has no len()\n",
      "\n",
      "During handling of the above exception, another exception occurred:\n",
      "\n",
      "Traceback (most recent call last):\n",
      "  File \"/home/ubuntu/.local/lib/python3.8/site-packages/IPython/core/interactiveshell.py\", line 2045, in showtraceback\n",
      "    stb = value._render_traceback_()\n",
      "AttributeError: 'TypeError' object has no attribute '_render_traceback_'\n",
      "\n",
      "During handling of the above exception, another exception occurred:\n",
      "\n",
      "Traceback (most recent call last):\n",
      "  File \"/home/ubuntu/.local/lib/python3.8/site-packages/IPython/core/ultratb.py\", line 1170, in get_records\n",
      "    return _fixed_getinnerframes(etb, number_of_lines_of_context, tb_offset)\n",
      "  File \"/home/ubuntu/.local/lib/python3.8/site-packages/IPython/core/ultratb.py\", line 316, in wrapped\n",
      "    return f(*args, **kwargs)\n",
      "  File \"/home/ubuntu/.local/lib/python3.8/site-packages/IPython/core/ultratb.py\", line 350, in _fixed_getinnerframes\n",
      "    records = fix_frame_records_filenames(inspect.getinnerframes(etb, context))\n",
      "  File \"/usr/lib/python3.8/inspect.py\", line 1503, in getinnerframes\n",
      "    frameinfo = (tb.tb_frame,) + getframeinfo(tb, context)\n",
      "  File \"/usr/lib/python3.8/inspect.py\", line 1461, in getframeinfo\n",
      "    filename = getsourcefile(frame) or getfile(frame)\n",
      "  File \"/usr/lib/python3.8/inspect.py\", line 708, in getsourcefile\n",
      "    if getattr(getmodule(object, filename), '__loader__', None) is not None:\n",
      "  File \"/usr/lib/python3.8/inspect.py\", line 737, in getmodule\n",
      "    file = getabsfile(object, _filename)\n",
      "  File \"/usr/lib/python3.8/inspect.py\", line 721, in getabsfile\n",
      "    return os.path.normcase(os.path.abspath(_filename))\n",
      "  File \"/usr/lib/python3.8/posixpath.py\", line 379, in abspath\n",
      "    cwd = os.getcwd()\n",
      "FileNotFoundError: [Errno 2] No such file or directory\n",
      "Traceback (most recent call last):\n",
      "  File \"/home/ubuntu/.local/lib/python3.8/site-packages/IPython/core/interactiveshell.py\", line 3418, in run_code\n",
      "    exec(code_obj, self.user_global_ns, self.user_ns)\n",
      "  File \"<ipython-input-13-97ade24e7925>\", line 1, in <module>\n",
      "    acc = history.history['accuracy']\n",
      "NameError: name 'history' is not defined\n",
      "\n",
      "During handling of the above exception, another exception occurred:\n",
      "\n",
      "Traceback (most recent call last):\n",
      "  File \"/home/ubuntu/.local/lib/python3.8/site-packages/IPython/core/interactiveshell.py\", line 2045, in showtraceback\n",
      "    stb = value._render_traceback_()\n",
      "AttributeError: 'NameError' object has no attribute '_render_traceback_'\n",
      "\n",
      "During handling of the above exception, another exception occurred:\n",
      "\n",
      "Traceback (most recent call last):\n",
      "  File \"/home/ubuntu/.local/lib/python3.8/site-packages/IPython/core/interactiveshell.py\", line 3338, in run_ast_nodes\n",
      "    if (await self.run_code(code, result,  async_=asy)):\n",
      "  File \"/home/ubuntu/.local/lib/python3.8/site-packages/IPython/core/interactiveshell.py\", line 3435, in run_code\n",
      "    self.showtraceback(running_compiled_code=True)\n",
      "  File \"/home/ubuntu/.local/lib/python3.8/site-packages/IPython/core/interactiveshell.py\", line 2047, in showtraceback\n",
      "    stb = self.InteractiveTB.structured_traceback(etype,\n",
      "  File \"/home/ubuntu/.local/lib/python3.8/site-packages/IPython/core/ultratb.py\", line 1436, in structured_traceback\n",
      "    return FormattedTB.structured_traceback(\n",
      "  File \"/home/ubuntu/.local/lib/python3.8/site-packages/IPython/core/ultratb.py\", line 1336, in structured_traceback\n",
      "    return VerboseTB.structured_traceback(\n",
      "  File \"/home/ubuntu/.local/lib/python3.8/site-packages/IPython/core/ultratb.py\", line 1193, in structured_traceback\n",
      "    formatted_exception = self.format_exception_as_a_whole(etype, evalue, etb, number_of_lines_of_context,\n",
      "  File \"/home/ubuntu/.local/lib/python3.8/site-packages/IPython/core/ultratb.py\", line 1151, in format_exception_as_a_whole\n",
      "    last_unique, recursion_repeat = find_recursion(orig_etype, evalue, records)\n",
      "  File \"/home/ubuntu/.local/lib/python3.8/site-packages/IPython/core/ultratb.py\", line 451, in find_recursion\n",
      "    return len(records), 0\n",
      "TypeError: object of type 'NoneType' has no len()\n",
      "\n",
      "During handling of the above exception, another exception occurred:\n",
      "\n",
      "Traceback (most recent call last):\n",
      "  File \"/home/ubuntu/.local/lib/python3.8/site-packages/IPython/core/interactiveshell.py\", line 2045, in showtraceback\n",
      "    stb = value._render_traceback_()\n",
      "AttributeError: 'TypeError' object has no attribute '_render_traceback_'\n",
      "\n",
      "During handling of the above exception, another exception occurred:\n",
      "\n",
      "Traceback (most recent call last):\n",
      "  File \"/home/ubuntu/.local/lib/python3.8/site-packages/IPython/core/interactiveshell.py\", line 2923, in _run_cell\n",
      "    return runner(coro)\n",
      "  File \"/home/ubuntu/.local/lib/python3.8/site-packages/IPython/core/async_helpers.py\", line 68, in _pseudo_sync_runner\n",
      "    coro.send(None)\n",
      "  File \"/home/ubuntu/.local/lib/python3.8/site-packages/IPython/core/interactiveshell.py\", line 3146, in run_cell_async\n",
      "    has_raised = await self.run_ast_nodes(code_ast.body, cell_name,\n",
      "  File \"/home/ubuntu/.local/lib/python3.8/site-packages/IPython/core/interactiveshell.py\", line 3357, in run_ast_nodes\n",
      "    self.showtraceback()\n",
      "  File \"/home/ubuntu/.local/lib/python3.8/site-packages/IPython/core/interactiveshell.py\", line 2047, in showtraceback\n",
      "    stb = self.InteractiveTB.structured_traceback(etype,\n",
      "  File \"/home/ubuntu/.local/lib/python3.8/site-packages/IPython/core/ultratb.py\", line 1436, in structured_traceback\n",
      "    return FormattedTB.structured_traceback(\n",
      "  File \"/home/ubuntu/.local/lib/python3.8/site-packages/IPython/core/ultratb.py\", line 1336, in structured_traceback\n",
      "    return VerboseTB.structured_traceback(\n",
      "  File \"/home/ubuntu/.local/lib/python3.8/site-packages/IPython/core/ultratb.py\", line 1211, in structured_traceback\n",
      "    formatted_exceptions += self.format_exception_as_a_whole(etype, evalue, etb, lines_of_context,\n",
      "  File \"/home/ubuntu/.local/lib/python3.8/site-packages/IPython/core/ultratb.py\", line 1151, in format_exception_as_a_whole\n",
      "    last_unique, recursion_repeat = find_recursion(orig_etype, evalue, records)\n",
      "  File \"/home/ubuntu/.local/lib/python3.8/site-packages/IPython/core/ultratb.py\", line 451, in find_recursion\n",
      "    return len(records), 0\n",
      "TypeError: object of type 'NoneType' has no len()\n",
      "\n",
      "During handling of the above exception, another exception occurred:\n",
      "\n",
      "Traceback (most recent call last):\n",
      "  File \"/home/ubuntu/.local/lib/python3.8/site-packages/IPython/core/interactiveshell.py\", line 2045, in showtraceback\n",
      "    stb = value._render_traceback_()\n",
      "AttributeError: 'TypeError' object has no attribute '_render_traceback_'\n",
      "\n",
      "During handling of the above exception, another exception occurred:\n",
      "\n",
      "Traceback (most recent call last):\n",
      "  File \"/home/ubuntu/.local/lib/python3.8/site-packages/IPython/core/ultratb.py\", line 1170, in get_records\n",
      "    return _fixed_getinnerframes(etb, number_of_lines_of_context, tb_offset)\n",
      "  File \"/home/ubuntu/.local/lib/python3.8/site-packages/IPython/core/ultratb.py\", line 316, in wrapped\n",
      "    return f(*args, **kwargs)\n",
      "  File \"/home/ubuntu/.local/lib/python3.8/site-packages/IPython/core/ultratb.py\", line 350, in _fixed_getinnerframes\n",
      "    records = fix_frame_records_filenames(inspect.getinnerframes(etb, context))\n",
      "  File \"/usr/lib/python3.8/inspect.py\", line 1503, in getinnerframes\n",
      "    frameinfo = (tb.tb_frame,) + getframeinfo(tb, context)\n",
      "  File \"/usr/lib/python3.8/inspect.py\", line 1461, in getframeinfo\n",
      "    filename = getsourcefile(frame) or getfile(frame)\n",
      "  File \"/usr/lib/python3.8/inspect.py\", line 708, in getsourcefile\n",
      "    if getattr(getmodule(object, filename), '__loader__', None) is not None:\n",
      "  File \"/usr/lib/python3.8/inspect.py\", line 737, in getmodule\n",
      "    file = getabsfile(object, _filename)\n",
      "  File \"/usr/lib/python3.8/inspect.py\", line 721, in getabsfile\n",
      "    return os.path.normcase(os.path.abspath(_filename))\n",
      "  File \"/usr/lib/python3.8/posixpath.py\", line 379, in abspath\n",
      "    cwd = os.getcwd()\n",
      "FileNotFoundError: [Errno 2] No such file or directory\n"
     ]
    }
   ],
   "source": [
    "acc = history.history['accuracy']\n",
    "val_acc = history.history['val_accuracy']\n",
    "\n",
    "loss = history.history['loss']\n",
    "val_loss = history.history['val_loss']\n",
    "\n",
    "epochs_range = range(EPOCHS)\n",
    "\n",
    "plt.figure(figsize=(8, 8))\n",
    "plt.subplot(1, 2, 1)\n",
    "plt.plot(epochs_range, acc, label='Training Accuracy')\n",
    "plt.plot(epochs_range, val_acc, label='Validation Accuracy')\n",
    "plt.legend(loc='lower right')\n",
    "plt.title('Training and Validation Accuracy')\n",
    "\n",
    "plt.subplot(1, 2, 2)\n",
    "plt.plot(epochs_range, loss, label='Training Loss')\n",
    "plt.plot(epochs_range, val_loss, label='Validation Loss')\n",
    "plt.legend(loc='upper right')\n",
    "plt.title('Training and Validation Loss')\n",
    "plt.show()"
   ]
  }
 ],
 "metadata": {
  "colab": {
   "machine_shape": "hm",
   "name": "SadOrHappy : facial expression classifeir",
   "provenance": []
  },
  "kernelspec": {
   "display_name": "Python 3",
   "language": "python",
   "name": "python3"
  },
  "language_info": {
   "codemirror_mode": {
    "name": "ipython",
    "version": 3
   },
   "file_extension": ".py",
   "mimetype": "text/x-python",
   "name": "python",
   "nbconvert_exporter": "python",
   "pygments_lexer": "ipython3",
   "version": "3.8.5"
  }
 },
 "nbformat": 4,
 "nbformat_minor": 1
}
